Workbook

Sheet ST公司
F1: 下一步 | H1: 退市概率
B2: 600136 | C2: 明诚 | D2: 湖北国企 | E2: 已经破除重组过了，正在优化资产负债表，目前收购了大股东的一个物业公司，估计是保壳用的。 | F2: 不知道装入什么资产 | G2: 干净壳 | H2: 低
B3: 600165 | C3: 宁科 | D3: 民营 | E3: 债务预期，可能要破产了 | F3: 破产 | H3: 中高
B4: 600190 | C4: 锦州港 | D4: 无控制人 | E4: 年报可能无法表示的意见，应收账款大量预期，违规担保 | F4: 强退 | H4: 高
B5: 600234 | C5: 科新发展 | D5: 民营 | E5: 2023年营收低于1亿。2024年预计可以摘帽营收大幅增加，利润转正 | F5: 摘帽 | G5: 干净壳 | H5: 低 | I5: 2023年年报带帽后大跌到5亿，然后触底后上涨
B6: 600243 | C6: 青海华鼎 | D6: 民营 | E6: 2024营收2.3亿不足3亿退市风险 | F6: 做大营收或利润或卖壳 | G6: 干净壳 | H6: 低 | I6: 大跌后可以抄底赌2025年摘帽
B7: 600287 | C7: 江苏舜天 | D7: 江苏国企 | E7: 前面多年财务造假，虚增收入，已经处罚完了 | F7: 摘帽 | G7: 干净壳 | H7: 低 | I7: 带帽后跌到10亿左右反弹
B8: 600289 | C8: 亿阳信通 | D8: 民营 | E8: 2023年年报无法表示意见、资金占用、违规担保，还有违规担保没解决 | F8: 解决担保问题 | H8: 低 | I8: 股价大涨过了，不用管
B9: 600358 | C9: 国旅联合 | D9: 江西国企 | E9: 2020年有几百万利润放错年份了，这个很好解决 | F9: 2026年可摘帽 | H9: 低 | I9: 跌停打开后反弹
B10: 600360 | C10: 华微电子 | D10: 民营 | E10: 2025年10月12前必须解决14亿的非经营资金占用问题，否则终止上市 | F10: 解决资产占用 | H10: 中 | I10: 占用有点多，2023年报披露后大跌到20亿反弹
B11: 600365 | C11: 通葡股份 | D11: 民营 | E11: 担保问题 | F11: 解决担保问题 | H11: 低
B12: 600381 | C12: 青海春天 | D12: 民营 | E12: 审计预测营收不足3亿，很多收入不符合常理，可能否定意见 | F12: 解决审计和营收 | G12: 干净壳
B13: 2289 | C13: 宇顺电子 | D13: 民营 | E13: 202308月大股东进入，现在需要保壳。正打算购买一些数据中心。 | F13: 保壳 | G13: 干净壳 | H13: 低 | I13: 已经大涨
B14: 600387 | C14: 海越能源 | D14: 银川国企 | E14: 2023年非标，2024又可能非标 | H14: 高
B15: 600462 | C15: 九有投资 | D15: 民营 | E15: 2023净资产为负，2024可能转正，但正被立案侦查。 | H15: 中
B16: 600568 | C16: 中珠医疗 | D16: 无控制人 | E16: 非经营资金占用5.6亿 | F16: 归还资金 | G16: 干净壳 | H16: 低
B17: 600599 | C17: 熊猫金控 | D17: 民营 | E17: 金融公司，小贷业务基本快没了。剩烟花业务了。2022-2023连续否定审计。业绩正的。 | F17: 解决历史问题 | G17: 干净壳 | H17: 低
B18: 600603 | C18: 广汇物流 | D18: 民营 | E18: 之前有小小的财务造假 | F18: 应该可以摘帽了 | H18: 低 | I18: 无投资价值了
B19: 600608 | C19: 宽频科技 | D19: 昆明国企 | E19: 原大股东资金占用3.4亿，已经10几年了，但原大股东已经没有偿还能力了。没有收入了，资产也很干净。2024年触发不足3亿退市风险。现大股东都10年了也没注入资产。 | F19: 做大营收或利润，注入资产 | G19: 干净壳 | H19: 低
B20: 2693 | C20: 双成药业 | D20: 民营 | E20: 收入不足。 本来要购买大股东的半导体资产，但最终终止了，因为跟有些交易方达不成一致。 | G20: 估值高 | H20: 中

Sheet 博弈记录
A1: 类型 | B1: 标的 | C1: 结果 | D1: 仓位 | E1: 收益 | F1: 买入日期 | G1: 最迟日期 | H1: 负债率 | I1: 转债规模 | J1: 现金 | K1: 转债现金比
A2: 不强赎 | B2: 金铜转债 | C2: 失败 | E2: -0.015 | F2: 20250731
A3: 年报延期 | B3: 天茂集团 | C3: 失败 | E3: -0.45
A4: 要约波动 | B4: 申科股份 | C4: 成功 | D4: 5000 | E4: 0.012 | F4: 20250721
A5: 要约波动 | B5: 申科股份 | C5: 成功 | D5: 10000 | E5: 0.01 | F5: 20250729
A6: 要约波动 | B6: 申科股份 | C6: 失败 | D6: 16000 | F6: 20250811
A7: 化债 | B7: 柳药集团 | G7: 20260112 | H7: 0.61 | I7: 8 | J7: 26 | K7: =I7/J7 -> 0.30769231
A8: 化债 | B8: 重庆建工 | C8: 失败 | D8: 10000 | F8: 20250811 | G8: 20251220 | H8: 0.9 | I8: 13 | J8: 40 | K8: =I8/J8 -> 0.325
A9: 化债 | B9: 烽火通信 | G9: 20251127 | H9: 0.63 | I9: 31 | J9: 39 | K9: =I9/J9 -> 0.79487179
A10: 化债 | B10: 鲁泰股份 | G10: 20260401 | H10: 0.28 | I10: 14 | J10: 30 | K10: =I10/J10 -> 0.46666667
A11: 化债 | B11: 利群股份 | C11: 失败 | G11: 20260401 | H11: 0.73 | I11: 13 | J11: 9 | K11: =I11/J11 -> 1.4444444
A12: 异议选择权 | B12: 海光信息 | C12: 成功 | D12: 27000 | E12: 0.036 | F12: 20250808
A13: 保壳 | B13: 清研 | G13: 20251231
A14: 保壳 | B14: 太和 | G14: 20251231
A15: 保壳 | B15: 凯鑫 | G15: 20251231
A16: 保壳 | B16: 海钦 | G16: 20251231
A17: 保壳 | B17: 海源 | G17: 20251231
A18: 保壳 | B18: 返利 | G18: 20251231
A19: 保壳 | B19: 威尔 | G19: 20251231
A20: 保壳 | B20: 艾艾 | G20: 20251231
A21: 保壳 | B21: 四通 | G21: 20251231
A22: 保壳 | B22: 亿通 | G22: 20251231
A23: 化债 | B23: 本钢板材 | C23: 失败 | G23: 20260629 | H23: 0.74 | I23: 56 | J23: 32 | K23: =I23/J23 -> 1.75

Sheet 摘帽
D1: 戴帽原因 | E1: 解决方法 | F1: 关键节点 | G1: 公布前市值 | H1: 公布前 | I1: 公布日 | J1: 摘帽当天 | K1: 第二天 | L1: 第三天
B2: 809 | C2: 和展能源 | D2: 2023亏损且收入不足1亿 | E2: 做大收入 | F2: 最低市值11亿，出现在20240424 20230830实控人变更为和展中达 | G2: 30 | H2: 翻倍 | J2: 高开低走 | K2: 0.0997 | L2: 0.0523
B3: 603023 | C3: 威帝 | D3: 2023亏损且收入不足1亿 | E3: 净利润正 | G3: 18 | H3: 翻倍 | I3: 涨停
B4: 688282 | C4: 理工导航 | D4: 2023年亏损且收入不足1亿 | E4: 收入做大 | F4: 20240403公告收购宇讯电子，1.2亿价款，宇讯电子收入7000万，利润1200万。 20240430带帽当天市值最低16亿。 20240605公告签定大额经营合同，1个多亿，年内交付，基本锁定摘帽。 20240830半年报显示业绩没有改善。 2241029三季报显示收入开始大涨。 20250117业绩预告显示收入满足1亿要求。 | G4: 40 | H4: 翻倍
B5: 600234 | C5: 科新发展 | D5: 2023年亏损且收入不足1亿 | E5: 做大收入和做正利润，实控人变更 | F5: 股价一直跌到20240611，晚上公告管理层增持计划。第二天开始股价反弹。最低市值5亿。 20240731公告实控人变更为连宗盛。股价继续上涨。 20240830半年报业绩没有改善。但公告新签合同2个多亿。 20240927公告出售广告子公司。 20241030三季报显示收入大涨。 20250125公告业绩预盈。 | G5: 18 | H5: 翻两倍 | I5: 0
B6: 600715 | C6: 文投控股 | D6: 2023净资产负、持续经营不确定性 | E6: 重整 | G6: 95 | H6: 涨50%
B7: 603879 | C7: 永悦科技 | D7: 2023内部否定审计 | G7: 18 | H7: 翻倍
B8: 603608 | C8: 天创时尚 | D8: 2023无法表示意见审计报告和否定意见内部审计 | E8: 解决相关事项 | G8: 21 | H8: 翻倍
B9: 603557 | C9: 起步股份 | D9: 2021年否定内部审计、2023年持续经营不确定性 | E9: 解决相关事项 | G9: 14 | H9: 0.7
B10: 506 | C10: 中润资源 | D10: 2023经营重大不确定性 | E10: 大股东为公司提供担保和借款 收回股权转让款 达成还款协议，解除账户冻结 聚焦黄金主业，增强经营能力 实控人变更为招远国企 | G10: 63 | H10: 7
B11: 2217 | C11: 合力泰 | D11: 2023净资产负、持续经营不确定性 | E11: 重整 | G11: 160 | H11: 1 | I11: -0.05
B12: 2310 | C12: 东方园林 | D12: 2023净资产负、持续经营不确定性 | E12: 重整 | G12: 121 | H12: 1 | I12: 0.03
B13: 2141 | C13: 贤丰控股 | D13: 2023亏损且收入不足1亿 2023否定内控报告： 1、1-2季度预收账款确认不当，说明收入相关内部控制有缺陷。 2、虚增收入成本，说明内部控制缺陷。 | E13: 靠覆铜板业务营收超过3亿 内部缺陷解决，前期会计差错纠正；批判相关人员 | G13: 22 | H13: 1 | I13: 0.05
B14: 2951 | C14: 金时科技 | D14: 2023年亏损且收入不足1亿 子公司四川金时印务有限公司实施停产已满3个月 | E14: 营收超过3亿 剥离停产的不良子公司 | F14: 2024年7月半年报预告时还没有摘帽的可能性，股价也一直跌到了这时候 20240822晚，公司发布公告出售停产子公司给关联方，总价3亿，股票开始涨停。 20241028三季报显示收入还只是有所提升，但离摘帽相差很远。 20241029、1114分别公告签订两项经营合同、总金额差不多3亿。储能相关业务。股价继续上涨。 20241231公告出售停产子公司完成。 20250125业绩预告，基本确定可以摘帽。 | G14: 32 | H14: 1 | I14: -0.05
B15: 525 | C15: 红太阳 | D15: 2023年否定内控报告 | E15: 非经营资金占用归还 对部分预付款项缺乏合理的商业理由和依据已完成整改 重整 | G15: 86 | H15: 0.2 | I15: -0.05
B16: 2259 | C16: 升达林业 | D16: 大股东违规担保 非经营资金占用 | E16: 解决相关事项 | G16: 23 | H16: 0.5 | I16: 0
B17: 989 | C17: 九芝堂 | D17: 2023年否定内控报告 | E17: 非经营资金3700万占用归还 | G17: 70 | H17: 0.3 | I17: 0.05
B18: 2052 | C18: 同洲电子 | D18: 2023亏损且收入不足1亿 经营不确定性 与大族控股有物业纠纷银行账户被冻结 | E18: 尝试重整没成功 开展算力服务电源业务改善收入和利润 投资者诉讼过期失效 | G18: 57 | H18: 7 | I18: 0.05 | J18: 0.05
B19: 300965 | C19: 恒宇信通 | D19: 2023亏损且收入不足1亿 经营不确定性，2023年一次性计提了前面8年的营业收入导致营收负数 | E19: 收入利润恢复正常 销售收入的审核价如果低于暂定价，就会计提营收，所以感觉很难确定以后不会作假 | G19: 22 | H19: 0.5 | I19: -0.04
B20: 600375 | C20: 汉马科技 | D20: 2023净资产负、持续经营不确定性 | E20: 重整 | G20: 90 | H20: 0.5 | I20: 0
B21: 2251 | C21: 步步高 | D21: 2023经营重大不确定性 | E21: 重整 | G21: 100 | H21: 0.7 | I21: 0.1 | J21: 0.1 | K21: 0.1 | L21: 0.1
B22: 600165 | C22: 宁科生物 | D22: 2023年无法表示意见的审计报告 | E22: 子公司重整中 退市风险解除了，但子公司持续经营能力未解除
B23: 300013 | C23: 新宁物流 | D23: 2023净资产负、持续经营不确定性 | E23: 定向增发融资优化财务状况，引入新大股东湖南国资
E33: =22*1.3 -> 28.6

Sheet 2023戴帽回测
B2: 名称 | C2: 戴帽当天收盘价 | D2: 戴帽当天打开跌停价 | E2: 2024年12月31收盘价 | F2: 申请摘帽当天开盘价 | G2: 摘帽当天开盘价 | H2: 戴帽当天到年底收益 | I2: 戴帽跌停打开到年底收益
B3: 恒宇信通 | C3: 27 | D3: 27 | E3: 35.81 | G3: 42.6 | H3: =E3/C3-1 -> 0.3262963 | I3: =E3/D3-1 -> 0.3262963
B4: 九芝堂 | C4: 8.1 | D4: 7.48 | E4: 7.96 | G4: 9.27 | H4: =E4/C4-1 -> -0.017283951 | I4: =E4/D4-1 -> 0.064171123
B5: 贤丰控股 | C5: 1.06 | D5: 0.96 | E5: 1.76 | F5: 2.15 | H5: =E5/C5-1 -> 0.66037736 | I5: =E5/D5-1 -> 0.83333333
B6: 合力泰 | C6: 1.22 | D6: 1.2 | E6: 2.39 | F6: 2.14 | H6: =E6/C6-1 -> 0.95901639 | I6: =E6/D6-1 -> 0.99166667
B7: 中润资源 | C7: 4.6 | D7: 2.75 | E7: 3.97 | H7: =E7/C7-1 -> -0.13695652 | I7: =E7/D7-1 -> 0.44363636
B8: 永悦科技 | C8: 4.84 | D8: 3.2 | E8: 3.84 | H8: =E8/C8-1 -> -0.20661157 | I8: =E8/D8-1 -> 0.2
B9: 天创时尚 | C9: 3.97 | D9: 2.92 | E9: 3.72 | H9: =E9/C9-1 -> -0.062972292 | I9: =E9/D9-1 -> 0.2739726
B10: 威帝股份 | C10: 2.75 | D10: 2.24 | E10: 2.74 | H10: =E10/C10-1 -> -0.0036363636 | I10: =E10/D10-1 -> 0.22321429
B11: 新宁物流 | C11: 1.95 | D11: 1.95 | E11: 3.47 | H11: =E11/C11-1 -> 0.77948718 | I11: =E11/D11-1 -> 0.77948718
B12: 天邦食品 | C12: 2.57 | D12: 2.32 | E12: 2.79 | H12: =E12/C12-1 -> 0.085603113 | I12: =E12/D12-1 -> 0.20258621
B13: 金时股份 | C13: 7.16 | D13: 7.16 | E13: 6.65 | H13: =E13/C13-1 -> -0.07122905 | I13: =E13/D13-1 -> -0.07122905
B14: 科新发展 | C14: 4.29 | D14: 2.71 | E14: 5.55 | H14: =E14/C14-1 -> 0.29370629 | I14: =E14/D14-1 -> 1.0479705
B15: 理工导航 | C15: 20.11 | D15: 20.11 | E15: 30.9 | H15: =E15/C15-1 -> 0.53654898 | I15: =E15/D15-1 -> 0.53654898
B16: 和展能源 | C16: 2.28 | D16: 2.28 | E16: 3.06 | H16: =E16/C16-1 -> 0.34210526 | I16: =E16/D16-1 -> 0.34210526
B17: 天沃科技 | C17: 3.56 | D17: 2.66 | E17: 3.83 | H17: =E17/C17-1 -> 0.075842697 | I17: =E17/D17-1 -> 0.43984962
B18: 汉马科技 | C18: 4.83 | D18: 5.04 | E18: 5.51 | H18: =E18/C18-1 -> 0.14078675 | I18: =E18/D18-1 -> 0.093253968
B19: 山东魔龙 | C19: 3.22 | D19: 2.87 | E19: 2.78 | H19: =E19/C19-1 -> -0.13664596 | I19: =E19/D19-1 -> -0.031358885

Sheet 退市
K1: 年份 | L1: 退市总数 | M1: ST退市 | N1: 其他退市 | O1: ST* | P1: 实际退市 | Q1: 退市率
B2: 代码 | C2: 公司 | D2: 原因 | E2: 详细 | F2: 思考 | G2: 确定日市值 | H2: 是否国资 | I2: 年底前收益 | K2: 2001 | L2: =M2+N2 -> 5 | M2: 3 | N2: 2
B3: 2750 | C3: 龙津药业 | D3: 财务退 | E3: 连续两年财务亏损营收不足。负债率是低的。 | F3: 为什么不卖壳呢？ | G3: 4 | H3: 否 | I3: 平 | K3: 2002 | L3: =M3+N3 -> 8 | M3: 7 | N3: 1
B4: 603963 | C4: 大理药业 | D4: 财务退 | E4: 连续两年财务亏损营收不足。负债率是低的。 | F4: 为什么不卖壳呢？ | G4: 2 | H4: 否 | I4: 负 | K4: 2003 | L4: =M4+N4 -> 4 | M4: 4
B5: 622 | C5: 恒立实业 | D5: 财务退 | E5: 2023年财务退市风险+保留意见审计报告+强调事项内控报告。 2024年无法及时披露年报 20250216实控人股份过户 | F5: 20240827实控人变更，总价1个亿，后面经过一系列努力还是没能挽救 | G5: 8 | H5: 否 | I5: 正 | K5: 2004 | L5: =M5+N5 -> 11 | M5: 8 | N5: 3
B6: 851 | C6: ST高鸿 | D6: 重大违法 | K6: 2005 | L6: =M6+N6 -> 12 | M6: 11 | N6: 1
B7: 600804 | C7: 鹏博士 | D7: 面值退 | E7: 2023年无法表示意见，资金占用，违规担保，立案调查。最终拒绝受理预重整。股价低于1元退市。2024继续无法表示意见。 | F7: 主要是非经营问题太多了。 | G7: 2 | I7: 平 | K7: 2006 | L7: =M7+N7 -> 11 | M7: 10 | N7: 1
B8: 627 | C8: 天茂集团 | D8: 主动退 | H8: 否 | K8: 2007 | L8: =M8+N8 -> 10 | M8: 6 | N8: 4
B9: 600837 | C9: 海通证券 | D9: 吸收合并 | H9: 是 | K9: 2008 | L9: =M9+N9 -> 2 | N9: 2
B10: 601519 | C10: 大智慧 | D10: 吸收合并 | H10: 否 | K10: 2009 | L10: =M10+N10 -> 6 | N10: 6
B11: 688041 | C11: 海光信息 | D11: 吸收合并 | H11: 是 | K11: 2010 | L11: =M11+N11 -> 4 | N11: 4
B12: 603213 | C12: 镇洋发展 | D12: 吸收合并 | H12: 是 | K12: 2011 | L12: =M12+N12 -> 3 | N12: 3
B13: 601989 | C13: 中国重工 | D13: 吸收合并 | H13: 是 | K13: 2012 | L13: =M13+N13 -> 4 | N13: 4
B14: 300379 | C14: ST东通 | D14: 重大违法 | K14: 2013 | L14: =M14+N14 -> 7 | M14: 2 | N14: 5
B15: 600200 | C15: ST苏吴 | D15: 重大违法 | K15: 2014 | L15: =M15+N15 -> 3 | M15: 1 | N15: 2
B16: 300280 | C16: ST紫天 | D16: 强制退 | E16: 拒绝整改，披露财务报告 | K16: 2015 | L16: =M16+N16 -> 10 | M16: 2 | N16: 8
B17: 920680 | C17: ST广道 | D17: 重大违法 | E17: 2018-2023连续虚假记载，2024定向发行股票说明书虚假记载 | I17: 负 | K17: 2016 | L17: =M17+N17 -> 2 | M17: 1 | N17: 1
B18: 600190 | C18: ST锦港 | D18: 重大违法 | E18: 连续三年虚假记载 | I18: 平 | K18: 2017 | L18: =M18+N18 -> 5 | M18: 2 | N18: 3
B19: 300208 | C19: ST中程 | D19: 财务退 | E19: 2023年净资产负，2024年保留意见审计报告和否定内控报告 | H19: 是 | I19: 平 | K19: 2018 | L19: =M19+N19 -> 6 | M19: 4 | N19: 2
B20: 600462 | C20: ST九有 | D20: 财务退 | E20: 2023年净资产负，2024无法表示意见的报告 | H20: 否 | I20: 平 | K20: 2019 | L20: =M20+N20 -> 12 | M20: 9 | N20: 3
B21: 584 | C21: ST工智 | D21: 财务退 | E21: 2023年无法表示意见，2024年又无法表示意见 | F21: 中间想购买资产来消除相关事项，但没成功 | H21: 否 | I21: 正 | K21: 2020 | L21: =M21+N21 -> 20 | M21: 17 | N21: 3 | O21: 98 | P21: 10 | Q21: =P21/O21 -> 0.10204082
B22: 600387 | C22: ST海越 | D22: 财务退 | E22: 2023年无法表示意见，2024年又无法表示意见 | G22: 4 | H22: 是 | I22: 平 | K22: 2021 | L22: =M22+N22 -> 23 | M22: 17 | N22: 6 | O22: 54 | P22: 22 | Q22: =P22/O22 -> 0.40740741
B23: 2336 | C23: ST人乐 | D23: 财务退 | E23: 2023年净资产负，2024年净资产负且无法表示意见 | F23: 公司中间也努力了，但是出售资产的进展没能在年末走完流程，因此无法确认收益。 | G23: 1.5 | H23: 是 | I23: 正 | K23: 2022 | L23: =M23+N23 -> 47 | M23: 42 | N23: 5 | O23: 45 | P23: 25 | Q23: =P23/O23 -> 0.55555556
B24: 603003 | C24: ST龙宇 | D24: 财务退 | E24: 2023年无法表示意见，2024年又无法表示意见 | F24: 大股东资金占用8亿未归还 20241216被立案调查 | H24: 否 | I24: 平 | K24: 2023 | L24: =M24+N24 -> 46 | M24: 43 | N24: 3 | O24: 53 | P24: 27 | Q24: =P24/O24 -> 0.50943396
B25: 600225 | C25: ST卓朗 | D25: 重大违法 | F25: 立案调查20240314-20141030 | H25: 是 | I25: 负 | K25: 2024 | L25: =M25+N25 -> 54 | M25: 46 | N25: 8 | O25: 57 | P25: 29 | Q25: =P25/O25 -> 0.50877193
B26: 601028 | C26: 玉龙股份 | D26: 主动退 | H26: 是 | K26: 2025 | L26: 32 | M26: 25 | N26: 6 | O26: 97 | P26: 20 | Q26: =P26/O26 -> 0.20618557
B27: 600705 | C27: 中航产融 | D27: 主动退 | H27: 是
B28: 300630 | C28: ST普利 | D28: 重大违法 | F28: 立案调查20240707-20250105 | G28: 4 | H28: 否 | I28: 负
B29: 600898 | C29: 国美通讯 | D29: 市值退 | E29: 市值低于5亿，2023年净资产负、收入低于1亿亏损 | F29: 立案调查20231206-20240415 公司没有努力 | G29: 2 | H29: 否 | I29: 正
B30: 600083 | C30: 博信股份 | D30: 市值退 | E30: 市值低于5亿，2023年净资产负，收入低于1亿亏损 | F30: 公司没有努力 | G30: 2 | H30: 是 | I30: 正
B31: 300108 | C31: ST吉药 | D31: 面值退 | E31: 2023年净资产负，打算重整，但没有拿到路条，最终股价低于1元 | F31: 2022-2023刚带帽摘帽，2024又带帽。实控人持股比例太低，可能没有动力。 | H31: 否 | I31: 负
B32: 603388 | C32: 元成 | D32: 重大违法 | H32: 否 | I32: 负
B33: 300344 | C33: 立方 | D33: 重大违法 | H33: 否
B34: 300391 | C34: ST长药 | D34: 重大违法 | H34: 否

Sheet 控股权变更
A1: 是否已经重组 | B1: 代码 | C1: 名称 | D1: 属性 | E1: 公告时间 | F1: 实际变更时间 | G1: 新实控人 | H1: 资产星级1-5，不知道默认0 | I1: 变更是否完成 | J1: 进展 | K1: 可转债 | L1: 代价（亿） | M1: 估值 | N1: 市值（亿） | O1: 营收（亿） | P1: 变更时资产规模（亿） | Q1: 净资产（亿） | R1: 实际注入间隔，单位年 | S1: 停牌时市值 | T1: 复牌后打开涨停市值
B2: 600684 | C2: 珠江股份 | D2: 广州国企 | E2: 20080101 | F2: =E2 -> 20080101 | G2: 广州国资，不知道会不会注入其他资产 | H2: 0 | I2: 完成 | J2: 剥离了房地产业务，目前剩物业业务和文体运营。 20241231，资产规模下降到17亿，原来330亿，负债从300下降到12亿 20250408，定向发行股票补充流动资金7.4亿。 20251014，发行2.5亿股，募资7.3亿 | L2: 0 | N2: 29 | O2: 16 | P2: 17 | Q2: 5 | R2: 0
A3: 是 | B3: 603268 | C3: 松发股份 | D3: 民营 | E3: 20181012 | G3: 恒力集团陈建华先生、范红卫女士夫妇29.91% | H3: 3 | I3: 完成 | J3: 一直到2024年都维持了原陶瓷业务，直到2024年再不进行资产注入就要触发不足3亿退市风险了，终于置入大股东的船舶资产，由于在变更控股权36个月之后进行的资产重组，不触发重组上市。。 | L3: 8.2 | N3: 20 | O3: 6 | P3: 12.6 | Q3: 7 | R3: 6 | S3: 17 | T3: 55
A4: 终止 | B4: 300489 | C4: 光智科技 | D4: 民营 | E4: 20190423 | G4: 朱世会6.8% 股份转让+表决权委托 | H4: 5 | I4: 完成 | J4: 20200224，定向发行4.5亿投资红外光学业务，子公司安徽中飞负责，注册资本9亿，与滁州市国资委一起 20200306，继续收购原实控人5%股份，花1亿 20200706，二股东王强转让股份给深圳富银城投 20200707，继续收购原实控人15%股份，花6.1亿 20210312，发行终止 20210430，红外业务开始开展，因投入过大，产生大量借款，负债率80%。 20211119，再次定向发行股票，7.2亿 20221206，又终止了 20230525，再次定向发行股票，5.5亿，发行价格一次比一次低 20240930，发布购买资产重大重组方案，收购实控人旗下先导电科，年净利润4亿，股价大涨3倍。这里终于知道为什么当时二股东要买股份了，肯定是深圳的相关企业。 20250627，终止。后卖给衢州发展，因为先导稀材在衢州投资了110亿项目。 | L4: 7.5 | N4: 26 | O4: 1.3 | P4: 5 | Q4: 3.7 | R4: 5 | S4: 31 | T4: 134
B5: 600076 | C5: 康欣新材 | D5: 国企 | E5: 20191111 | F5: =E5 -> 20191111 | G5: 无锡国资委，无锡建发受让15%+表决权委托13% | H5: 0 | I5: 完成 | J5: 20181218，首次转让9%，6.2亿 20191018，二次转让6%，4.3亿 20210202，向大股东定向发行募资8.5亿，发行后无锡建发占38% | L5: =6.2+4.3+8.5 -> 19 | N5: 40 | O5: 6 | P5: 71 | Q5: 40 | R5: 0
A6: 是 | B6: 301297 | C6: 富乐德 | D6: 民营 | E6: 20200101 | G6: 上海申和，无实际控制人 | H6: 4 | I6: 完成 | J6: 202410，购买大股东旗下资产富乐华，3亿净利润，定价65亿，大涨2倍。功率半导体覆铜陶瓷载板 | R6: 4 | S6: 66 | T6: 200
A7: 是 | B7: 603991 | C7: 至正股份 | D7: 民营 | E7: 20200521 | G7: 正信同创的王强受让27% ，旗下有深圳市国弘半导体发展有限公司，深圳市旅游（集团）股份有限公司。资本运作高手 | H7: 4 | I7: 完成 | J7: 王强还持有哈尔滨中飞新技术股份有限公司15%（20200724已经转让给基金公司），沈阳商业城股份有限公司5.6%（已退市） 20201128，向原大股东转让亏损资产，4.1亿 20201224，终止重大资产出售 20221109，收购苏州桔云科技51%股权，半导体湿法工艺设备，1.1亿 20241024，发行股份购买大股东的先进封装材料国际有限公司半导体资产并且置出原至正新材料资产，估值37亿，5个涨停。净资产39亿，净利润7000万 | L7: 6.2 | N7: 20 | O7: 3 | P7: 5.7 | Q7: 3.7 | R7: 4 | S7: 46 | T7: 74
B8: 603168 | C8: 莎普爱思 | D8: 民营 | E8: 20200530 | F8: =E8 -> 20200530 | G8: 养和投资的林弘立、林弘远受让7%，原来持有9%+表决权放弃，旗下有医院资产，天伦医院、明好医院 | H8: 2 | I8: 完成 | J8: 2021年内二次股份转让5% 20240924，大股东同业竞争延期3年，到2027年底，主要是医院还不符合注入的条件 | L8: 4.1 | N8: 30 | O8: 3.5 | P8: 16 | Q8: 13 | R8: 0
B9: 600738 | C9: 丽尚国潮 | D9: 国企 | E9: 20200725 | F9: =E9 -> 20200725 | G9: 丽水经开区的元明控股受让20% | H9: 0 | I9: 完成 | J9: 20210729，公开挂牌转让兰州红楼房地产开发有限公司股权，8亿 20211012，未能征集到受让方，终止出售 20250103，向大股东定向发行募资7.1亿，已终止 | L9: 10 | N9: 50 | O9: 6 | P9: 33 | Q9: 17 | R9: 0
B10: 601599 | C10: 浙文影业 | D10: 国企 | E10: 20200826 | F10: =E10 -> 20200826 | G10: 浙江财政厅的浙江文投受让表决权17%，旗下有很多影视公司，有同业竞争问题 | H10: 0 | I10: 完成 | J10: 20210608，定向发行募资6亿完成，浙江文投持有23%股份和16%的表决权 | L10: 6 | N10: 26 | O10: 17 | P10: 38 | Q10: 6 | R10: 0
B11: 600966 | C11: 博汇纸业 | D11: 民营 | E11: 20200828 | F11: =E11 -> 20200828 | G11: 金光纸业的黄志源股份转让28.81%，合计持有48%，外商独资。承诺6年内解决同业竞争问题。经查询，金光纸业2022年净资产740亿，净利润46亿；2023年净利润36亿 | H11: 1 | I11: 完成 | J11: 还没有注入过资产 | L11: 20 | N11: 65 | O11: 97 | P11: 193 | Q11: 48 | R11: 0
B12: 603306 | C12: 华懋科技 | D12: 民营 | E12: 20201020 | F12: =E12 -> 20201020 | G12: 袁晋清先生、林晖 不知道到底想干嘛 | H12: 0 | I12: 完成 | J12: 20230221，一致行动人宁波新点减持股份到5%以下。 20250522，购买华懋东阳子公司剩余股权。 | L12: 12 | N12: 60 | O12: 9.5 | P12: 27 | Q12: 24 | R12: 0
B13: 603223 | C13: 恒通股份 | D13: 国企 | E13: 20201119 | F13: =E13 -> 20201119 | G13: 龙口市东江街道南山村村民委员会的南山集团受让20%+表决权委托5%。旗下资产规模巨大，2020年净利润40亿。持有南山铝业44%，南山智尚科技股份有限公司67%，山东裕龙石化有限公司51%，石化公司规模很大 | H13: 3 | I13: 完成 | J13: 20220809，向南山集团定向发行募资24亿，占比41% 期间，陆续收购了大股东旗下一些港口资产 20240731，要约收购5%股份 | L13: 34 | N13: 50 | O13: 55 | P13: 19 | Q13: 13 | R13: 0
B14: 300211 | C14: 亿通科技 | D14: 民营 | E14: 20210204 | F14: =E14 -> 20210204 | G14: 黄汪，股份转让29.99%，旗下有安徽华米做健康监测设备，2024年末营收15亿，净利润8800万，净资产25亿。可能注入上市公司。 公司每季度财报都非常详实。 | H14: 3 | I14: 完成 | J14: 2021控股后，发展了传感器和芯片业务 | L14: 9.5 | N14: 24 | O14: 0.8 | P14: 5 | Q14: 4.6 | R14: 0
B15: 603159 | C15: 上海亚虹 | D15: 民营 | E15: 20210206 | F15: =E15 -> 20210206 | G15: 海南宁生旅游，孙林，29.99%，文旅公司 | H15: 1 | I15: 完成 | L15: 5 | N15: 21 | O15: 6.7 | P15: 6.4 | Q15: 4.6 | R15: 0
B16: 603110 | C16: 东方材料 | D16: 民营 | E16: 20210223 | F16: =E16 -> 20210223 | G16: 许广彬29.9% | H16: 0 | I16: 完成 | J16: 20250603，大股东股份被司法拍卖后只剩5%，基本无用了 | L16: 7.6 | N16: 22 | O16: 4 | P16: 8 | Q16: 6.5 | R16: 0
B17: 2857 | C17: 三晖电气 | D17: 民营 | E17: 20210420 | F17: =E17 -> 20210420 | G17: 上海长耘，胡坤，20%，不知道有什么资产 | H17: 0 | I17: 完成 | J17: 2023年开始涉猎储能设备 | L17: 4.5 | N17: 17 | O17: 2.2 | P17: 6.3 | Q17: 5.1 | R17: 0
B18: 603677 | C18: 奇精机械 | D18: 国企 | E18: 20210506 | F18: =E18 -> 20210506 | G18: 浙江宁波工投，宁波国资委，29.99% | H18: 0 | I18: 完成 | J18: 不知道什么资产 | L18: 8.8 | N18: 22 | O18: 15.6 | P18: 20.5 | Q18: 10 | R18: 0
B19: 603909 | C19: 建发合诚 | D19: 国企 | E19: 20211113 | F19: =E19 -> 20211113 | G19: 福建厦门益悦，厦门国资委16%，下面主要是房地产公司，也有一些其他的，建发集团下面很多 | H19: 0 | I19: 完成 | J19: 入驻后，发展了很大的建筑施工业务，收入规模做大了。 | L19: 5.4 | N19: 24 | O19: 8 | P19: 15 | Q19: 10 | R19: 0
B20: 600300 | C20: 维维股份 | D20: 国企 | E20: 20211127 | F20: =E20 -> 20211127 | G20: 江苏徐州市新盛投资控股集团有限公司，徐州国资委，29.99% | H20: 0 | I20: 完成 | J20: 20190801，转让17%给新盛集团，公司变更为无实际控制人 20200805，转让枝江酒业股权给江苏综艺控股集团，4.6亿 20211127，继续转让12%给新盛集团，变更为徐州国资委 20230429，江苏综艺为枝江酒业的欠款做担保 | L20: =9.5+9.1 -> 18.6 | N20: 48 | O20: 50 | P20: 67 | Q20: 30 | R20: 0
B21: 600645 | C21: 中源协和 | D21: 民营 | E21: 20211215 | F21: =E21 -> 20211215 | G21: 陈春梅、龚虹嘉原持有10%，受让表决权7%。生命健康领域投资人。知名资本大佬。同时6亿参与ST长药的重整 | H21: 0 | I21: 完成 | J21: 20231228大股东继续增持了一些股份，目前持有表决权25% | L21: 0 | N21: 100 | O21: 15 | P21: 50 | Q21: 35 | R21: 0
B22: 600222 | C22: 太龙药业 | D22: 国企 | E22: 20220125 | F22: =E22 -> 20220125 | G22: 河南郑州高新区国资委受让14% | H22: 0 | I22: 完成 | L22: 8 | N22: 56 | O22: 16 | P22: 37 | Q22: 17 | R22: 0
B23: 603903 | C23: 中持股份 | D23: 国企 | E23: 20220310 | F23: =E23 -> 20220310 | G23: 长江环保受让5%+定向发行后总共24%，无实际控制人 | H23: 0 | I23: 完成 | L23: 8 | N23: 15 | O23: 37 | P23: 13 | Q23: 0 | R23: 0
B24: 603458 | C24: 勘设股份 | D24: 国企 | E24: 20220329 | F24: =E24 -> 20220329 | G24: 贵州贵阳国资委23%，定向发行股份 | H24: 0 | I24: 已终止 | J24: 2024，发行获得通过，但一直未启动，估计要黄 | L24: 9.5 | N24: 23 | O24: 14 | P24: 58 | Q24: 31 | R24: 0
B25: 603922 | C25: 金鸿顺 | D25: 民营 | E25: 20220409 | F25: =E25 -> 20220409 | G25: 海南众德科技，刘栩29.99%，旗下物业和商业公司 | H25: 0 | I25: 完成 | J25: 2023年剥离了一些子公司 20241106，发行股份收购新思考马达公司，非大股东资产。2024净利润1亿。 | L25: 7.5 | M25: 25 | N25: 25 | O25: 5 | P25: 12.5 | Q25: 10 | R25: 0
B26: 600388 | C26: 龙净环保 | D26: 国企 | E26: 20220531 | F26: =E26 -> 20220531 | G26: 紫金矿业，股份转让15%+表决权委托10%。新能源平台 | H26: 1 | I26: 完成 | J26: 20221021，收购大股东旗下的一些新能源业务，4700万 20230721，定向发行股票15亿搞储能等项目 20231202，终止发行 都是自己新开一些新能源发电，感觉注入资产的量也不大 | L26: 17 | N26: 113 | O26: 113 | P26: 270 | Q26: 170 | R26: 0
B27: 300269 | C27: 联建光电 | D27: 民营 | E27: 20220907 | F27: =E27 -> 20220907 | G27: 广东南峰谭炜樑，环保和房地产公司 | H27: 1 | I27: 完成 | J27: 剥离了一些子公司，目前负债率还是太高 | L27: 2.1 | N27: 22 | O27: 12 | P27: 12 | Q27: 0.4 | R27: 0
B28: 603078 | C28: 江化微 | D28: 国企 | E28: 20221201 | F28: =E28 -> 20221201 | G28: 山东淄博财政局23.95%，股份转让+定向发行 | H28: 0 | I28: 完成 | L28: 14 | N28: 60 | O28: 5.6 | P28: 20 | Q28: 11 | R28: 0
B29: 603990 | C29: 麦迪科技 | D29: 国企 | E29: 20230105 | F29: =E29 -> 20230105 | G29: 皓祥控股，绵阳安州区国资委16% | H29: 0 | I29: 完成 | J29: 20250128，剥离光伏子公司给大股东，5.9亿，感觉有戴帽的风险 | L29: =3.3+2.2 -> 5.5 | M29: ================================================================== | N29: 34 | O29: 3 | P29: 16 | Q29: 13 | R29: 0
B30: 603088 | C30: 宁波精达 | D30: 国企 | E30: 20230110 | F30: =E30 -> 20230110 | G30: 通商集团，浙江宁波国资委29.99% | H30: 0 | I30: 完成 | J30: 20240430，发行股票购买无锡微研股权，3.6亿，非关联人公司。2个涨停不到 20250522，收购完成 | L30: 10 | M30: ST组合策略8只仓位8.7。 | N30: 33 | O30: 6.5 | P30: 13.4 | Q30: 6.4 | R30: 0
B31: 600243 | C31: 青海华鼎 | D31: 民营 | E31: 20230131 | F31: =E31 -> 20230131 | G31: 王封，股份很少，主要是一致行动人，感觉没什么意思 | H31: 0 | I31: 完成 | L31: 2 | M31: ================================================================== | N31: 17 | O31: 3.5 | P31: 10 | Q31: 7 | R31: 0
B32: 600193 | C32: 创兴资源 | D32: 民营 | E32: 20230401 | F32: =E32 -> 20230401 | G32: 华侨实业余增云受让23.9% | H32: 1 | I32: 完成 | J32: 20241109，余增云被杭州上城公安局立案，涉嫌集资诈骗。 20250530，余增云股份被司法拍卖 | L32: 5.4 | M32: 博重组策略3只仓位1.92。 | N32: 23 | O32: 2.6 | P32: 7 | Q32: 2.5 | R32: 0
B33: 603016 | C33: 新宏泰 | D33: 国企 | E33: 20230408 | F33: =E33 -> 20230408 | G33: 江苏无锡国资委，是原大股东减持后升级为大股东的 | H33: 0 | I33: 完成 | J33: 20200102，首次转让15%给无锡国资委 20201225，继续转让12%给无锡国资委 | L33: =3.3+4.4 -> 7.7 | M33: ================================================================== | N33: 24 | O33: 6 | P33: 10 | Q33: 8 | R33: 0
B34: 300536 | C34: 农尚环境 | D34: 民营 | E34: 20230616 | F34: =E34 -> 20230616 | G34: 林峰（公司总经理）20%，实控人过往有多年半导体从业经历，算力服务和显示驱动芯片。 | H34: 2 | I34: 完成 | J34: 已经在开展算力服务相关业务了 | L34: 7.1 | M34: 低估红利仓位10.85。 | N34: 42 | O34: 0.7 | P34: 10 | Q34: 6 | R34: 0
B35: 603136 | C35: 天目湖 | D35: 国企 | E35: 20230701 | F35: =E35 -> 20230701 | G35: 溧阳城发受让26%，溧阳人民政府 | H35: 0 | I35: 完成 | J35: 20211019，城发受让11.19% 20220719，城发受让8.7% 20230701，城发受让6.5% | L35: 11 | M35: =L35/0.26 -> 42.307692 | N35: 42 | O35: 4 | P35: 16 | Q35: 12 | R35: 0
B36: 603685 | C36: 晨丰科技 | D36: 民营 | E36: 20230801 | F36: =E36 -> 20230801 | G36: 丁闵受让20%+表决权放弃+定向发行，发行后占38% | H36: 1 | I36: 完成 | J36: 20230510，签订受让股票协议同时，向丁闵收购麒麟新能等电力公司。同时定向发行募资4.4亿 202309，收购资产完成，3.6亿，牛逼啊，相当于用大股东自己募资的钱买自己的公司，左右口袋互换，股票还多了。 20250410，定向发行获得批复 | K36: 是 | L36: 3.3 | N36: 17 | O36: 12 | P36: 36 | Q36: 12 | R36: 0
B37: 603196 | C37: 日播时尚 | D37: 民营 | E37: 20230901 | F37: =E37 -> 20230901 | G37: 上海阔元梁丰受让29.72% | H37: 1 | I37: 完成 | J37: 20230516，变更实控人的同时，收购新实控人的新能源电池正极材料资产，置出上市公司原服装资产。本次交易构成重组上市，10个涨停。 20231106，终止重大资产置换。重组上市太难了。 20241101，发行股份购买茵地乐71%股权，20亿，锂电池粘结剂，不是大股东的资产，但向大股东募集资金。2024年净利润2亿。6个涨停。 20250520，向原大股东转让日播致胜子公司，1.3亿 | L37: 7.1 | N37: 22 | O37: 10 | P37: 12 | Q37: 7 | R37: 0
B38: 600540 | C38: 新赛股份 | D38: 国企 | E38: 20230905 | F38: =E38 -> 20230905 | G38: 中新建物流，新疆生产建设兵团国资委29.16%，物流资产整合 | H38: 1 | I38: 完成 | L38: 7.3 | N38: 23 | O38: 13 | P38: 26 | Q38: 7 | R38: 0
B39: 603578 | C39: 三星新材 | D39: 民营 | E39: 20230906 | F39: =E39 -> 20230906 | G39: 金玺泰有限公司受让14.15%+定向发行，金银山 | H39: 1 | I39: 完成 | J39: 20230628，公司向金银山实控国华金泰增资4000万，控股。主要是做光伏玻璃的。 20250320，发行股票5.6亿得到批复，等待发行 2023-2024股东资产大幅增加，就是国华金泰的业务导致，刚好赶上下行期。 | L39: 5.25 | N39: 37 | O39: 10 | P39: 27 | Q39: 12 | R39: 0
B40: 603778 | C40: 国晟科技 | D40: 民营 | E40: 20230908 | F40: =E40 -> 20230908 | G40: 国晟能源，吴君、高飞先转让8%，2.1亿，又转让8%，4.1亿。电力行业 | H40: 0 | I40: 完成 | J40: 20240601，继续定向发行5.4亿 | L40: 6.4 | N40: 40 | O40: 21 | P40: 32 | Q40: 14 | R40: 0
...

Sheet 预计摘帽
B1: 利润转正>收入足够，实控人变更加10%概率，负债率太高且没有预重整的排除 | N1: 10 | O1: 10 | P1: 70 | Q1: 30 | R1: 40 | S1: 80 | T1: 5 | U1: 20 | V1: -40 | W1: 30
A2: 年份 | B2: 代码 | C2: 名称 | D2: 警示原因 | E2: 解决措施 | F2: 进展 | G2: 关注点 | H2: 其他 | I2: 财报审计报告 | J2: 内控审计报告 | K2: 是否变更实控人 | L2: 重整 | M2: 摘帽分 | N2: 实控人变更权重 | O2: 变更完成权重 | P2: 出售资产权重 | Q2: 购买资产权重 | R2: 收入增加权重 | S2: 利润转正权重 | T2: 国企权重 | U2: 大合同权重 | V2: 审计扣分 | W2: 腾笼换鸟权重 | X2: 题材分 | Z2: 财报问询
A3: 2025 | B3: 595 | C3: 宝塔实业 | D3: 收入不足3亿，差1亿 | E3: 收入超过3亿或净利润转正 | F3: 已经注入宁夏电投新能源资产 | G3: 宁夏自治区 | I3: 标准无保留意见 | J3: 标准无保留意见 | K3: 否 | M3: =N3+O3+P3+Q3+R3+S3+T3+U3+V3+W3 -> 95 | N3: 0 | O3: 0 | P3: 30 | Q3: 30 | R3: 0 | S3: 0 | T3: 5 | U3: 0 | V3: 0 | W3: 30
A4: 2025 | B4: 2058 | C4: 威尔泰 | D4: 收入不足退市风险 | E4: 向大股东出售仪器仪表相关的亏损资产包2.8亿，净利润转正负债率大幅下降。然后向大股东购买紫江新材，从事软包锂电池用铝塑复合膜的研发。两者不互为前提，独立进行。紫江新材在新三板上市。2024年报显示收入6亿利润5000万，但利润在下滑 大股东拥有紫江企业（饮料包装、软塑包装）、紫江新材 | F4: 2024年1219公告资产重组。 20250401公告出售资产审计已经完成。就等股东大会批准了，价格2.8亿。资产1.6亿，负债6000万，增值170%，主要是紫竹高新的长期股权（穿透后是房地产）投资的增值。出售完成后净利润转正。 购买资产还在审计。 20250510公告，购买控股子公司紫燕机械剩余49%股权，4300万。2024年净利润1578万。提高净利润的措施。资产1.5亿，负债6400万 20250513公告，出售资产议案合并到0527股东大会一起审议 20250527，出售和购买都获得股东大会通过。 20250605，出售资产完成交割和收款，收购资产也完成了，二季度利润转正应该没问题了 半年报净利润还是略亏 20250828半年报净利润-400万，紫燕机械半年收入3000万，净利润350万，紫江新材半年报收入和净利润也增长30%。 | G4: 关注出售亏损资产进展 | H4: 壳价值也够低了 | I4: 标准无保留意见 | J4: 标准无保留意见 | K4: 否 | M4: =N4+O4+P4+Q4+R4+S4+T4+U4+V4+W4 -> 90 | N4: 0 | O4: 0 | P4: 30 | Q4: 30 | R4: 0 | S4: 10 | T4: 0 | U4: 0 | V4: 0 | W4: 20
A5: 2025 | B5: 300899 | C5: 上海凯鑫 | D5: 收入不足退市风险 | E5: 2024年Q4的收入异常的低。导致了最后的亏损。 一季度利润转正、收入大涨 在手订单2.3亿 | F5: 半年报净利润2000万，收入1.2亿 | G5: 关注半年报 | H5: 壳价值也够低了 | I5: 标准无保留意见 | J5: 标准无保留意见 | K5: 否 | M5: =N5+O5+P5+Q5+R5+S5+T5+U5+V5+W5 -> 85 | N5: 0 | O5: 0 | P5: 0 | Q5: 0 | R5: 40 | S5: 40 | T5: 0 | U5: 5 | V5: 0 | W5: 0
A6: 2025 | B6: 600753 | C6: 庚星股份/海钦股份 | D6: 收入不足退市风险 净资产负退市风险 持续经营不确定其他风险 | E6: 20240320原大股东股份被拍卖过户，现大股东钟仁海成为新实控人，3.9亿，单价7。然后与原大股东展开了争夺公司实际控制权的长时间斗争。钟仁海有鸿基石化股份公司，2023净资产12亿，净利润140万。 虽然公司现在净资产负，但负债规模仅1个亿多，只需要大股东随便融资就能解决。 目前看大股东还是有一些能力的，逐渐解决了很多的问题，跟二股东也和解了 20240105证监会对公司违法行为立案调查，现在还没有结论 | F6: 20241031大股东财务资助7000万 一季度净利润大幅减亏，管理销售费用大幅下滑，经营液化石油气业务，从收入上看，全年3亿应该没有问题。 半年报预计净利润500万，算起来净资产应该可以转正 20250822半年报，净资产已经转正 20250908公告，大股东赠送51%子公司股权给上市公司，净资产8000万，5-7月收入3000万，净利润100万，这下净资产稳了 | G6: 关注净资产的解决进展 | I6: 强调无保留 强调项：持续经营不确定性 被立案调查，原控股股东和上市公司 | J6: 强调无保留 强调项：原公司内控缺陷多，现在已整改 | K6: 是 | M6: =N6+O6+P6+Q6+R6+S6+T6+U6+V6+W6 -> 60 | N6: 10 | O6: 10 | P6: 0 | Q6: 15 | R6: 0 | S6: 40 | T6: 0 | U6: 0 | V6: -15
A7: 2025 | B7: 1270 | C7: 铖昌科技 | D7: 收入不足3亿，差9000万 | E7: 收入超过3亿或净利润转正 | F7: 一季度收入大涨，净利润大幅转正。主要是需求增加。 半年报净利润4500万 | G7: 相控雷达芯片，遥感卫星。 | I7: 标准无保留意见 | J7: 标准无保留意见 | K7: 否 | M7: =N7+O7+P7+Q7+R7+S7+T7+U7+V7+W7 -> 73 | N7: 0 | O7: 0 | P7: 0 | Q7: 0 | R7: 13 | S7: 60 | T7: 0 | U7: 0 | V7: 0
A8: 2025 | B8: 603580 | C8: 艾艾精工 | D8: 收入不足退市风险 不过亏得也不多 | E8: 20250429拟花1.25亿购买泰州中石信资产，资产年收入5000万，净利润300万，资产的客户都是果链。预测2025年收入1.2亿，利润1800万，5月有产品量产。 靠收入保3亿有点悬，靠利润转正还是有可能的 | F8: 一季度利润转正，转正原因是财务费用下降，估计是汇率影响。 20250515购买资产议案通过股东大会决议 20250526，中石信完成工商变更。 半年报净利润800万，收入1亿，财务费用就贡献了600万，中石信6月并表贡献了800万，可以预估下半年贡献收入4800万，按收入算3个亿还是有点难 三季报大增1.9亿，净利润1200万 | G8: 警惕固定资产减值，存货跌价，应收账款减值，其他非流动资产减值 | I8: 标准无保留意见 | J8: 标准无保留意见 | K8: 否 | M8: =N8+O8+P8+Q8+R8+S8+T8+U8+V8+W8 -> 50 | N8: 0 | O8: 0 | P8: 0 | Q8: 10 | R8: 0 | S8: 40 | T8: 0 | U8: 0 | V8: 0 | X8: 5
A9: 2025 | B9: 600636 | C9: 国新文化 | D9: 收入不足3亿，差0.2亿，主要是商誉减值4.5亿导致亏损。还剩2.5亿商誉。 | E9: 收入超过3亿或净利润转正 | F9: 20250408，大股东发布增持1%-2%计划。 一季度收入大涨，AI相关，有部分去年的收入在一季度确认。净利润减亏。 半年报收入1.1亿。大增，净利润690万转正 三季报大增2.3亿，净利润1700万 | G9: 现金13亿，国资委 | I9: 标准无保留意见 | J9: 标准无保留意见 | K9: 否 | M9: =N9+O9+P9+Q9+R9+S9+T9+U9+V9+W9 -> 50 | N9: 0 | O9: 0 | P9: 0 | Q9: 0 | R9: 5 | S9: 40 | T9: 5 | U9: 0 | V9: 0
A10: 2025 | B10: 2656 | C10: 摩登大道 | D10: 收入不足3亿，差0.9亿 | E10: 收入超过3亿 | F10: 20250415公告，收购电缆公司，2024收入1亿，净利润600万 20250507公告，收购电力公司完成 半年报2.3亿，大涨，净利润减亏。其中电力公司并表9100万，净利润200万。所有保留事项已经消除。 三季报4.2亿收入 | G10: 原大股东占用2.4亿，被责令归还快到期时被现实控人代替归还，现大股东王立平旗下有锐洋集团，产值25亿。持有10%股份，还有3%的表决权 | I10: 保留意见 | J10: 保留意见 | K10: 是 | M10: =N10+O10+P10+Q10+R10+S10+T10+U10+V10+W10 -> 70 | N10: 5 | O10: 5 | P10: 0 | Q10: 20 | R10: 40 | S10: 0 | T10: 0 | U10: 0 | V10: 0
A11: 2025 | B11: 300268 | C11: 佳沃食品 | D11: 净资产负 | F11: 20250425出售主要净资产负的子公司给大股东，完成净资产大幅提升，净利润大幅提升。只剩青岛国星子公司，收入8亿，净利润6000万。 20250610出售完成 半年报净资产转正，剥离子公司贡献净利润-3.18亿，青岛国星受关税25%影响，进口成本上升，销量下滑，净利润下滑到1400万。 | I11: 持续经营不确定性无保留意见 | J11: 标准无保留意见 | K11: 否 | M11: =N11+O11+P11+Q11+R11+S11+T11+U11+V11+W11 -> 50 | N11: 0 | O11: 0 | P11: 50 | Q11: 0 | R11: 0 | S11: 0 | T11: 0 | U11: 0 | V11: 0
A12: 2025 | B12: 2529 | C12: 海源复材 | D12: 收入不足退市风险，差1.3亿 | E12: 换实控人 主营光伏组件和汽车复合材料和光伏组件代工业务 提高代工业务是不是就可以保收入了 | F12: 20250331实控人变更新余金紫欣的刘洪超、丁立中、刘浩 ，总价3.5亿 20250416设立江西省紫源新技术有限责任公司，搞电力的。 20250417，金紫欣向公司提供1亿财务资助 20250428，一季度收入9600万大涨，说是光伏和复合材料订单增加 20250428担保公告，从中找到一季度收入大涨的主要功臣是新余海源电源科技有限公司子公司收入大涨。Q1就超过了去年一年的收入。 二季度收入继续大涨 20250825，剥离压机资产，净资产可提升1.2亿，2024年收入4000万 半年报收入2亿，净利润下滑 三季报大增2.7亿 | I12: 标准无保留意见 | J12: 标准无保留意见 | K12: 是 | M12: =N12+O12+P12+Q12+R12+S12+T12+U12+V12+W12 -> 40 | N12: 10 | O12: 10 | P12: 0 | Q12: 0 | R12: 20 | S12: 0 | T12: 0 | U12: 0 | V12: 0
A13: 2025 | B13: 518 | C13: 四环生物 | D13: 收入不足退市风险，差1亿 | E13: 20250114原大股东股份被拍卖，新大股东碧水投资进入。已经完成变更。花了3.8亿。好像是搞农业的。 | F13: 一季度收入下降，净利润大幅下滑 半年报预计收入1.7亿，大幅增加，主要是苗木增加 三季报大增2.9亿 | G13: 不知道实控人有什么资产 | I13: 标准无保留意见 | J13: 标准无保留意见 | K13: 是 | M13: =N13+O13+P13+Q13+R13+S13+T13+U13+V13+W13 -> 50 | N13: 10 | O13: 10 | P13: 0 | Q13: 0 | R13: 30 | S13: 0 | T13: 0 | U13: 0 | V13: 0
A14: 2025 | B14: 600228 | C14: 返利网 | D14: 收入不足3亿，差7000万 | E14: 收入超过3亿 | F14: 半年报收入1.8亿，净利润-3000万 三季报已经过3亿 | I14: 标准无保留意见 | J14: 标准无保留意见 | K14: 否 | M14: =N14+O14+P14+Q14+R14+S14+T14+U14+V14+W14 -> 40 | N14: 0 | O14: 0 | P14: 0 | Q14: 0 | R14: 40 | S14: 0 | T14: 0 | U14: 0 | V14: 0 | Z14: 三季报
A15: 2025 | B15: 300211 | C15: 亿通科技 | D15: 收入不足退市风险，9600万 | E15: 2021年3月实控人变更为黄汪，旗下有安徽华米做健康监测设备，2024年末营收15亿，净利润8800万，净资产25亿。可能注入上市公司。 公司每季度财报都非常详实。 | F15: 一季度收入大涨 20250430跟安徽华米签订关联交易合同1.5亿，1年内有效。 三季报大增1.5亿 | G15: 收入保壳基本没问题 大股东注入资产的时间也够了，但是华米现在自己也不太好，不知道符不符合注入条件 | I15: 标准无保留意见 | J15: 标准无保留意见 | K15: 是 | M15: =N15+O15+P15+Q15+R15+S15+T15+U15+V15+W15 -> 65 | N15: 10 | O15: 10 | P15: 0 | Q15: 0 | R15: 40 | S15: 0 | T15: 0 | U15: 5 | V15: 0
A16: 2025 | B16: 288 | C16: 绿康生化 | D16: 2024净资产负 持续经营不确定性 | E16: 20250422变更实控人，跨境物流公司福建纵腾网络有限公司，2024年利润11个亿。这个估计肯定要注入了。同时出售原负债资产给原大股东，两者不互为前提。大股东原29.99%股份全部转让。原光伏胶膜资产置出后，资产负债表将得到极大的改善。还参与了有棵树的破除重整 | F16: 一季度收入利润没有改善 要等资产出售进展和实控人变更进展 20250528，置出资产承接方设立完成 20250628出售草案出炉 | G16: 关注资产出售情况 关注实控人变更情况 | I16: 带解释的无保留意见 解释段是持续经营不确定性 | J16: 标准无保留意见 | K16: 是 | M16: =N16+O16+P16+Q16+R16+S16+T16+U16+V16+W16 -> 30 | N16: 10 | O16: 0 | P16: 20 | Q16: 0 | R16: 0 | S16: 0 | T16: 0 | U16: 0 | V16: 0
A17: 2025 | B17: 603007 | C17: 花王股份 | D17: 收入不足退市风险 | E17: 已经重整过了，2025年必须要解决收入不足的问题，否则投资人就亏死了。正在购买三方资产混动燃油箱，12个亿，购买1半的股权，如果成功，肯定可以满足收入要求了。明年可以摘帽。 大股东还有新质生产力资产，但注入较慢，为了保壳所以先购买三方资产，目前看市场不认可公布购买方案后一直跌。从监管函得知，公司购买的三方资产定价明显过高，偏离汽车零部件行业太多，公司账上现金一共就5个多亿，却全部拿来购买高价资产，目的是什么？所以投资者用脚投票。 大股东旗下还有半导体资产等待注入。 | F17: 实控人变更承诺被第一次股东大会否决，现第二次股东大会继续审议。就算通过能否购买成功也不一样，参照双成药业。 20250604，回复购买资产预案的问询，2024年净利润7000万，按这个看，也不算很贵。竞对公司，世昌股份 20250830，购买资产已经过户完成。预计增加2025年并表收入2.3亿 | G17: 关注实控人承诺变更是否获得股东大会通过 | H17: 市值太高 | I17: 标准无保留意见 | J17: 标准无保留意见 | K17: 是 | M17: =N17+O17+P17+Q17+R17+S17+T17+U17+V17+W17 -> 30 | N17: 10 | O17: 10 | P17: 0 | Q17: 10 | R17: 0 | S17: 0 | T17: 0 | U17: 0 | V17: 0
A18: 2025 | B18: 3004 | C18: 声讯股份 | D18: 收入不足3亿 | E18: 收入超过3亿，差了3000万 | F18: 一季度收入持平，净利润继续下滑 20250614收购浙江中辰城市应急服务管理有限公司51%股权，2024年收入1.4亿，净利润-1500万，0630完成收购，保壳应该没问题了 半年报收入7000万，同比增2000万，净利润减亏，经营在好转 三季报收入1.3亿，净利润继续正，但这主要是减值转回导致的，转回了2700万。还是有点担心Q4的收入 | I18: 标准无保留意见 | J18: 标准无保留意见 | K18: 否 | M18: =N18+O18+P18+Q18+R18+S18+T18+U18+V18+W18 -> 30 | N18: 0 | O18: 0 | P18: 0 | Q18: 20 | R18: 10 | S18: 0 | T18: 0 | U18: 0 | V18: 0
A19: 2025 | B19: 2569 | C19: 步森股份 | D19: 收入不足退市风险 持续经营不确定性 | E19: 202407实控人变更为宝鸡国资，司法拍卖获得，1.6亿，7.5元/股。 | F19: 一季度收入下滑，净利润减亏，减亏原因是信用减值下滑。 半年报收入下滑，净利润增亏，公司管理层正在股东方的支持下努力缓解现金流压力，多措并举恢复和发展主营业务 20250908公告，出售联营公司陕西步森服饰智造有限公司，按长期股权投资项预计，可以卖6000万 | I19: 强调无保留意见 强调项：连续三年亏损，现金流负 持续经营不确定性 | J19: 强调事项段无保留意见 强调项：原大股东非经营资金占用，已归还。 | K19: 是 | M19: =N19+O19+P19+Q19+R19+S19+T19+U19+V19+W19 -> 25 | N19: 10 | O19: 10 | P19: 0 | Q19: 0 | R19: 0 | S19: 0 | T19: 5 | U19: 0 | V19: 0
A20: 2025 | B20: 504 | C20: 南华生物 | D20: 收入不足退市风险 | E20: 说是要发展美妆 大股东旗下有财信证券 | F20: 一季度没有改善 20250811公告收购湖南慧泽生物医药科技有限公司51%股权CRO 20250903华7000万控股娄底金弘新材料新能源电池回收，前7月收入4500万，业绩承诺每年2.5亿 三季报收入0.8亿，但净利润转正，通过管理费用大幅下降完成的 | G20: 关注保壳信号 | I20: 标准无保留意见 | J20: 标准无保留意见 | K20: 否 | M20: =N20+O20+P20+Q20+R20+S20+T20+U20+V20+W20 -> 45 | N20: 0 | O20: 0 | P20: 0 | Q20: 20 | R20: 0 | S20: 20 | T20: 5 | U20: 0 | V20: 0
A21: 2025 | B21: 603721 | C21: 中广天择 | D21: 收入不足退市风险 2024年就差1000万 | E21: 20250430拟购买大股东旗下体育资产，年收入4000万，净利润300万 | F21: 一季度收入大幅下滑 20250430收购大股东旗下长沙体育产业经营有限公司，2024年收入6900万，净利润300万 202506收购完成股权变更登记。 半年报略减，1.3亿，全年应该差的不多，长沙体产并表收入1300万 三季报略减1.8亿，进入两家私募 | G21: 关注保壳信号 | I21: 标准无保留意见 | J21: 标准无保留意见 | K21: 否 | M21: =N21+O21+P21+Q21+R21+S21+T21+U21+V21+W21 -> 25 | N21: 0 | O21: 0 | P21: 0 | Q21: 20 | R21: 0 | S21: 0 | T21: 5 | U21: 0 | V21: 0
A22: 2025 | B22: 688511 | C22: 天微电子 | D22: 收入不足退市风险 | E22: 无 | F22: 一季度利润转正大涨 三季报净利润3000万 | G22: 关注业绩持续性 | H22: 壳价值也够低了 | I22: 标准无保留意见 | J22: 标准无保留意见 | K22: 否 | M22: =N22+O22+P22+Q22+R22+S22+T22+U22+V22+W22 -> 60 | N22: 0 | O22: 0 | P22: 0 | Q22: 0 | R22: 0 | S22: 60 | T22: 0 | V22: 0 | Z22: 半年报
A23: 2025 | B23: 603389 | C23: 亚振家居 | D23: 收入不足退市风险 | E23: 20250424，实控人变更，总价款7个多亿，分两步，先转让29.99%股份，股份过户后十工作日内发起要约，要约21%股份，要约价格5.68 新实控人是向其旗下公司借款收购股份的，旗下公司进行锆钛矿开采业务，净资产超100亿。还有一家三板企业400122，原游久股份，稀土资产，该公司目前不太好。 | F23: 一季度收入略增利润减亏 20250530，变更完成 20250821收购广西锆业科技有限公司51%股权完成，前5月收入1.2亿 半年报收入1亿，净利润-3000万 三季报不变1.5亿 | G23: 关注实控人变更完成情况 | I23: 标准无保留意见 | J23: 标准无保留意见 | K23: 是 | M23: =N23+O23+P23+Q23+R23+S23+T23+U23+V23+W23 -> 20 | N23: 10 | O23: 10 | P23: 0 | Q23: 0 | R23: 0 | S23: 0 | T23: 0 | U23: 0 | V23: 0
A24: 2025 | B24: 2898 | C24: 塞隆药业 | D24: 收入不足退市风险 | E24: 就差5000万 20250518转让给海南雅亿，合伙人企业，无实际控制人，医药行业，2亿，8元/股。 | F24: 一季度收入利润继续下滑 20250524，海南雅亿完成工商变更。 20250710，变更完成 半年报收入1.3亿，净利润继续下滑 三季报收入2亿同比下滑一点 | G24: 关注保壳信号 | I24: 标准无保留意见 | J24: 标准无保留意见 | K24: 是 | M24: =N24+O24+P24+Q24+R24+S24+T24+U24+V24+W24 -> 20 | N24: 10 | O24: 10 | P24: 0 | Q24: 0 | R24: 0 | S24: 0 | T24: 0 | U24: 0 | V24: 0
A25: 2025 | B25: 603838 | C25: 四通股份 | D25: 收入不足退市风险 | E25: 有新业务增加收入，本来差得也不多，按照2024年3个月的矿产品收入3700万计算，今年7400万，总收入肯定超过3亿了。 | F25: 目前看一季度收入增加3000多万，大概率就是矿产品的 半年报业绩收入1.7亿 三季报大增2.6亿 | G25: 关注未来季度财报 | H25: 壳价值也够低了 | I25: 标准无保留意见 | J25: 标准无保留意见 | K25: 否 | M25: =N25+O25+P25+Q25+R25+S25+T25+U25+V25+W25 -> 30 | N25: 0 | O25: 0 | P25: 0 | Q25: 0 | R25: 30 | S25: 0 | T25: 0 | U25: 0 | V25: 0
A26: 2025 | B26: 2762 | C26: 金发拉比 | D26: 收入不足退市风险 | E26: 一季度收入大涨，可能解除风险，合并了几个医疗门诊的收入。 | F26: 一季度收入大涨，合并医疗门诊收入 半年报，收入1.6亿，亏损扩大，其中医美3300万，其他母婴用品增加了4700万 三季报2.6亿收入 | G26: 关注未来季度财报 | H26: 壳价值也够低了 | I26: 标准无保留意见 | J26: 标准无保留意见 | K26: 否 | M26: =N26+O26+P26+Q26+R26+S26+T26+U26+V26+W26 -> 30 | N26: 0 | O26: 0 | P26: 0 | Q26: 0 | R26: 30 | S26: 0 | T26: 0 | U26: 0 | V26: 0
A27: 2025 | B27: 3032 | C27: 传智教育 | D27: 收入不足3亿，差6000万 | E27: 收入超过3亿或净利润转正 | F27: 20240920，收购辅仁控股海外教育公司，2023年收入8000万，净利润1000万。20250104收购完成。 20241220，收购三板公司优优汇联51%股权，1亿。2024收入5000万，净利润-800万。20250213已完成。 一季度收入略涨（主要并表辅仁控股），净利润减亏 半年报收入1.6亿，净利润大幅减亏，-1000万，其中并表辅仁4600万，净利润500万，优优260万净利润-400万 三季报大增2.6亿 | G27: 感觉收入还是有点风险，看看半年报预告再说 公司账上8亿现金。 | I27: 标准无保留意见 | J27: 标准无保留意见 | K27: 否 | M27: =N27+O27+P27+Q27+R27+S27+T27+U27+V27+W27 -> 30 | N27: 0 | O27: 0 | P27: 0 | Q27: 0 | R27: 30 | S27: 0 | T27: 0 | U27: 0 | V27: 0
A28: 2025 | B28: 603813 | C28: 原尚股份 | D28: 收入不足退市风险 | E28: 20250429收购零部件制造公司，收入2700万，利润100万 | F28: 一季度继续恶化，原汽车零部件物流业务继续收缩。汽车零部件业务拓展。 半年报收入略增，1.8亿。净利润增亏 20250823，打算剥离农牧资产，2025上半年收入1000万，利润略亏。 三季报收入3.3亿 | G28: 关注努力信号 | I28: 标准无保留意见 | J28: 标准无保留意见 | K28: 否 | M28: =N28+O28+P28+Q28+R28+S28+T28+U28+V28+W28 -> 40 | N28: 0 | O28: 0 | P28: 0 | Q28: 0 | R28: 40 | S28: 0 | T28: 0 | U28: 0 | V28: 0 | Z28: 三季报
A29: 2025 | B29: 600130 | C29: 波导股份 | D29: 收入不足退市风险 | E29: 收入就差2000万，还是有希望的，账上现金7个亿，随便买个资产 | F29: 一季度没有改善 半年报收入大增，净利润下降为负 三季报大增3.2亿 | G29: 关注保壳信号 | I29: 标准无保留意见 | J29: 标准无保留意见 | K29: 否 | M29: =N29+O29+P29+Q29+R29+S29+T29+U29+V29+W29 -> 40 | N29: 0 | O29: 0 | P29: 0 | Q29: 0 | R29: 40 | S29: 0 | T29: 0 | U29: 0 | V29: 0
A30: 2025 | B30: 2199 | C30: 东晶电子 | D30: 收入不足3亿，差1亿 | E30: 收入超过3亿 | F30: 一季度收入净利润没改善 20250527控制权变更，股权投资行业 20250806完成变更 半年报收入1.1亿，还差不少 三季报1.8亿 | I30: 标准无保留意见 | J30: 标准无保留意见 | K30: 否 | M30: =N30+O30+P30+Q30+R30+S30+T30+U30+V30+W30 -> 20 | N30: 10 | O30: 10 | P30: 0 | Q30: 0 | R30: 0 | S30: 0 | T30: 0 | U30: 0 | V30: 0
A31: 2025 | B31: 600892 | C31: 大晟文化 | D31: 收入不足退市风险 | E31: 暂无 | F31: 一季度收入没有改善 半年报收入增长30%到1亿，净利润增亏到-3000万，主要源于短剧业务的收入3000万，还新增了7个传媒子公司猜测是要通过短剧来扩大收入。但是净资产只剩4000万了，感觉下半年很可能亏到负资产。 三季报大增2亿，但是净资产要负了 20251227，大股东豁免3000万债务 | G31: 关注保壳信号 | I31: 标准无保留意见 | J31: 标准无保留意见 | K31: 是 | M31: =N31+O31+P31+Q31+R31+S31+T31+U31+V31+W31 -> 5 | N31: 5 | O31: 5 | P31: 0 | Q31: 0 | R31: 0 | S31: 0 | T31: 5 | U31: 0 | V31: -10
A32: 2025 | B32: 2816 | C32: 和科达 | D32: 收入不足退市风险 | E32: 20241023实控人变成国企了，已经完成。2022年报退市风险，2023年报撤摘帽。2024年报又退市风险。 | F32: 一季度利润转正、收入大涨，不过一季度明显有调节收入的嫌疑。 二季度利润转亏 三季报收入大增1.7亿，净利润-200万 | G32: 关注二季度 | H32: 壳价值也够低了 | I32: 标准无保留意见 | J32: 标准无保留意见 | K32: 是 | M32: =N32+O32+P32+Q32+R32+S32+T32+U32+V32+W32 -> 15 | N32: 10 | O32: 10 | P32: 0 | Q32: 0 | R32: 0 | S32: -10 | T32: 5 | U32: 0 | V32: 0
A33: 2025 | B33: 691 | C33: 亚太实业 | D33: 净资产负 | E33: 净资产转正 | F33: 20250702，预重整 2025实控人增持1000万，还要增持2000万 20250903，原实控人和现实控人内讧了 | G33: 202307表决权委托给债务方广州万顺，实控人变更，实控人旗下有一些5G通信等资产 | I33: 重大段落的无保留意见 欠广州万顺的借款逾期了 | J33: 标准无保留意见 | K33: 是 | L33: 是 | M33: =N33+O33+P33+Q33+R33+S33+T33+U33+V33+W33 -> 15 | N33: 5 | O33: 10 | P33: 0 | Q33: 0 | R33: 0 | S33: 0 | T33: 0 | U33: 0 | V33: 0
A34: 2025 | B34: 2789 | C34: 建艺集团 | D34: 净资产负 | E34: 净资产转正 | F34: 20250411，向大股东出售子公司广东建艺矿业有限公司股权大概10亿，该公司净资产只有1000万，这是变相的输血，但没有进展 20251225，大股东豁免14亿债务，赠送4亿现金 | G34: 关注建艺矿业出售进展 关注重整的可能性 | I34: 持续经营不确定性无保留意见 | J34: 持续经营不确定性无保留意见 | K34: 否 | L34: 否 | M34: =N34+O34+P34+Q34+R34+S34+T34+U34+V34+W34 -> 15 | N34: 0 | O34: 0 | P34: 10 | Q34: 0 | R34: 0 | S34: 0 | T34: 5 | U34: 0 | V34: 0
A35: 2025 | B35: 2047 | C35: ST宝鹰 | D35: 净资产负 | E35: 差的不多，4000万足够转正 | F35: 珠海国资委是2020年从古少明买过来控股权的，花了16亿 20240721，要约收购13%的股份 2024年曾想通过无偿捐赠现金规避带星，但被审计判断不合规 2024年已经剥离了主要负债资产 20250725公开转让净资产-61万的子公司，标价3000万 20250911，控股股东无偿划转给珠光集团，主要做涉港澳资产运营的 大股东变更 | I35: 标准无保留意见 | J35: 否定意见，但问题不大 | K35: 否 | M35: =N35+O35+P35+Q35+R35+S35+T35+U35+V35+W35 -> 25 | N35: 10 | O35: 0 | P35: 10 | Q35: 0 | R35: 0 | S35: 0 | T35: 5 | U35: 0 | V35: 0 | W35: 0
A36: 2025 | B36: 301288 | C36: 清研环境 | D36: 收入不足1亿，差3000万 | E36: 收入超过1亿或净利润转正 | F36: 20250321，竞拍福建海通镍业公司51%股权，2024年收入8000万，净利润负。固体垃圾处理回收。 一季度收入持平，净利润减亏，主要是管理费用下降和毛利提高。 20250506，福建镍业完成工商变更。那这个时间算，全年能合并收入4500万，差不多够1亿 半年报收入下降到2500万，镍业公司并表650万，目前看还是有点危险的，但是公司存货里有半成品和未验收部分一共5000万，这部分如果在下半年验收就足够1亿了 三季报收入1亿，够了 | G36: 关注二季度合并镍业后的收入。主要原主业也大幅下降 | I36: 标准无保留意见 | J36: 标准无保留意见 | K36: 否 | M36: =N36+O36+P36+Q36+R36+S36+T36+U36+V36+W36 -> 50 | N36: 0 | O36: 0 | P36: 0 | Q36: 10 | R36: 40 | S36: 0 | T36: 0 | U36: 0 | V36: 0
A37: 2025 | B37: 668 | C37: 荣丰控股 | D37: 收入不足3亿 | E37: 收入超过3亿 公司今年以销售长春国金中心即可完成业绩 | F37: 一季度收入大涨，主要是房地产销售 三季报大增1.8亿 | G37: 关注二季度情况 | I37: 标准无保留意见 | J37: 标准无保留意见 | K37: 否 | M37: =N37+O37+P37+Q37+R37+S37+T37+U37+V37+W37 -> 10 | N37: 0 | O37: 0 | P37: 0 | Q37: 0 | R37: 10 | S37: 0 | T37: 0 | U37: 0 | V37: 0
A38: 2025 | B38: 2214 | C38: 大立科技 | D38: 收入不足3亿 | E38: 收入超过3亿 | F38: 20250110签订7100万研发合同。 一季度收入大涨，应该是因为2024年部分收入在一季度确认。 半年报收入大增至1.4亿，但还是危险 三季报大增2.6亿 | G38: 应收和存货都很高，财务有些问题。 | I38: 标准无保留意见 | J38: 标准无保留意见 | K38: 否 | M38: =N38+O38+P38+Q38+R38+S38+T38+U38+V38+W38 -> 10 | N38: 0 | O38: 0 | P38: 0 | Q38: 0 | R38: 10 | S38: 0 | T38: 0 | U38: 0 | V38: 0
A39: 2025 | B39: 820 | C39: 神雾节能 | D39: 收入不足退市风险 | E39: 20250110，持股49%表决权53%的子公司江苏院与其少数股东中清孚尧的子公司签订10亿合同，预期20260331完工。 | F39: 一季度收入大幅下降，净利润减亏 20250802，半年报收入大幅下降，净利润减亏 3亿合同150日内完成，20250819 大股东部分股权要被拍卖，如果全部拍卖完成，控制权可能变更，大股东看来自身难保 三季报略减9000万 | G39: 关注合同履行情况 | I39: 标准无保留意见 | J39: 标准无保留意见 | K39: 否 | M39: =N39+O39+P39+Q39+R39+S39+T39+U39+V39+W39 -> 10 | N39: 0 | O39: 0 | P39: 0 | Q39: 0 | R39: 0 | S39: 0 | T39: 0 | U39: 10 | V39: 0
A40: 2025 | B40: 2168 | C40: 惠程科技 | D40: 收入不足且净资产负 | E40: 净资产转正 收入超过3亿或利润转正 202105变更的控制权。 | F40: 20241010，大股东免除1亿债务 20241218,4700万购买锐恩医药51%股权，2024收入1.6亿，净利润2000万，净资产1600万 一季度收入大涨，利润减亏，主要是合并了锐恩医药，负资产还没进展 半年报医药收入1亿。净利润2300万 20250930，豁免了1.3亿债务，净资产转正。收入2.8亿，净利润大幅减亏 打算重整 20251229，重整投资人赠送3000万现金 | G40: 年终净资产还是可能变负 | I40: 标准无保留意见 | J40: 标准无保留意见 | K40: 否 | L40: 是 | M40: =N40+O40+P40+Q40+R40+S40+T40+U40+V40+W40 -> 6 | N40: 0 | O40: 0 | P40: 0 | Q40: 0 | R40: 1 | S40: 0 | T40: 5 | U40: 0 | V40: 0
...

Sheet 重整
C1: 法院 | D1: 被债权人申报 | E1: 临时管理人 | F1: 债权申报 | G1: 招募产业投资人 | H1: 确定投资人 | I1: 签署重整协议 | J1: 中间进展 | K1: 是否立案调查 | L1: 批准时带星 | M1: 法院批准受理重整 | N1: 重整债权申报 | O1: 重整计划批准 | P1: 转增股本实施 | Q1: 结果 | R1: 刚兑上限 | S1: 批准受理后走势 | U1: 批准时市值 | V1: 除权后下跌
A2: 2822 | B2: ST中装 | C2: 深圳中院 | D2: 20240622 | F2: 20240808 | H2: 20250228 | I2: 20250307，康恒环境，净资产116亿，净利润13亿，生活垃圾发电。转增10亿股，1.55元 产投3.04亿股，占16% | L2: 否 | M2: 20250820 | N2: 20250822 | R2: 5 | S2: 下跌 | U2: 35
A3: 300391 | B3: 长药控股 | C3: 十堰中院 | D3: 20250121 | E3: 上海市锦天城律师事务所 | F3: 20250123 | G3: 20250123 | H3: 24家报名，20250506四川嘉道博文生态科技有限公司、十堰市昊炜生物科技发展有限公司 | I3: 20250508 转增5.2亿，2.42/股。 嘉道博文：5.9亿 昊伟生物：2500万 抵债价格：不低于10元 | J3: 必须在2025年底之前重整完成，否则就要退市 审计都OK的 股价一直跌，是不是因为重大的诉讼一直没停。 可能被立案调查 | K3: 是 | Q3: 失败
A4: 2742 | B4: 三圣股份 | C4: 重庆五中院 | D4: 20240928 | G4: 20240930 | H4: 冀衡集团药业的 | I4: 1.53元，转赠2.5亿股 1.6亿给投资人 | L4: 是 | M4: 20250809 | N4: 20250813 | R4: 5 | S4: 下跌 | U4: 26
A5: 2713 | B5: 东易日盛 | C5: 北京一中院 | D5: 20241018 | E5: 20241107北京大成律师事务所 | F5: 20241109 | G5: 20241130 | H5: 15家产投、25家财投。20250319，北京华著科技有限公司，智算中心 | I5: 20250319 财投8亿，2.6亿股，后修改为4元一股，因此估计大涨 产投：2.3元，1.5亿股，3.4亿 | M5: 20251119
A6: 300117 | B6: 嘉寓股份 | C6: 北京一中院 | D6: 20240603 | E6: 20240718北京市海问律师事务所 | F6: 20240717 | G6: 20240717 | H6: 20240913北京道荣合利科技集团有限公司和北京久银投资控股股份有限公司组成的联合体 | I6: 20240927 | J6: 20241021，原财务投资人全部退出，引入新财务投资人，且减少财务投资份额 20241114，产业投资人解除重整协议，理由是预计公司无法在可见时间内完成前置审批 | Q6: 失败
A7: 300125 | B7: 聆达股份 | C7: 六安中院 | D7: 20240731 | E7: 20240731金寨县人民政府组建的清算小组 | F7: 20240802 | G7: 20240923 | H7: 20241128 浙江众凌科技有限公司和合肥威迪变色玻璃有限公司联合体，半导体的 | I7: 转赠4亿股 财投价3.87 | J7: 中途有财投退出，重新引入 | L7: 是 | M7: 20251118
A8: 2200 | B8: ST交投 | C8: 昆明中院 | D8: 20250424 | E8: 20250605上海市通力律师事务所（主办机构）与国浩律师（昆明）事务所（辅助机构），临时管理人负责人为刘嘉诚律师。 | F8: 20250606-20240705 | G8: 20250614 要求产投资金总额超500亿，净额200亿，这典型的量身定制 | H8: 大股东自己重整自己，真恶心10转14.5共2.6亿股 | I8: 产投：3.87元，3500万股 财投：4.67元，1.68亿股 | J8: 必须在2025年底之前重整完成，否则就要退市 审计都OK的 | L8: 是 | M8: 20251024 | N8: 20251024 | S8: 下跌
A9: 430 | B9: 张家界 | C9: 张家界中院 | D9: 20241018 | E9: 张家界旅游集团有限公司清算组 | F9: 20241029 | G9: 20241029 | H9: 电广传媒和芒果超媒等财投，没有产投，所以原来的还是大股东 | I9: 财投，3.96元，3.225亿股 财投2，7.3元，0.41亿股 | L9: 否 | M9: 20251103
A10: 300209 | B10: 有棵树 | C10: 长沙中院 | D10: 20240220 | E10: 有棵树科技股份有限公司清算组 | F10: 20240315 | G10: 20240830 | H10: 46家，产投3家 | I10: 20241116，深圳市天行云供应链、福建纵腾网络有限公司 1.85亿转增股票，3.6亿，单价1.95。2.3亿股留给财投。7000万抵债，10元。刚兑上限100万。 | J10: 20241212，与财投签署协议 | M10: 20240930 | N10: 20241008 | O10: 20241207 | P10: 2241219 | Q10: 成功 | R10: 100 | S10: 上涨 | U10: 18
A11: 2217 | B11: 合力泰 | C11: 福州中院 | D11: 20240305 | E11: 合力泰科技股份有限公司清算组 | F11: 20240312 | G11: 20240511 | H11: 没有，不需要 | I11: 20241130 | M11: 20241125 | N11: 20241130 | O11: 20241224 | P11: 20241225 | Q11: 成功 | R11: 0 | S11: 下跌 | U11: 84
A12: 600375 | B12: 汉马科技 | C12: 马鞍山中院 | D12: 20240127 | M12: 20241109 | O12: 20241212 | Q12: 成功 | R12: 10 | S12: 下跌
A13: 603363 | B13: 傲农生物 | C13: 漳州中院 | D13: 20240323 | M13: 20241106 | O13: 20241211 | Q13: 成功 | R13: 35 | S13: 横盘 | U13: 34
A14: 2124 | B14: 天邦食品 | C14: 宁波中院 | D14: 20240319 | H14: 20250509厦门建发物产有限公司联合体 | I14: 产投：1.85元，2亿股 财投：2.1元，1亿股
A15: 2325 | B15: 洪涛股份 | C15: 深圳中院 | D15: 20240130 | E15: 20240430 | F15: 20240529 | G15: 20240531 | J15: 20240731不予受理 | Q15: 失败
A16: 656 | B16: 金科股份 | C16: 重庆五中院 | D16: 20230523 | M16: 20240423 | O16: 20250512
A17: 908 | B17: 景峰医药 | C17: 龙口法院 | D17: 20231102 | E17: 20231118 | G17: 20240802，招募条件里就感觉是因人而设，提前已经有沟通了 | H17: 20240828石药集团 | I17: 20250429 石药集团，8.7亿股，1元/股，石药5.26亿股 | L17: 否 | M17: 20251022 | S17: 上涨
A18: 300506 | B18: 名家汇 | C18: 深圳中院 | D18: 20240731 | G18: 20240910 | H18: 20241129，新余领九投资管理中心 | I18: 20250228，7.3亿股，1.47元 | L18: 否 | M18: 20250930
A19: 300338 | B19: 开元教育 | C19: 长沙中院 | D19: 20240629 | E19: 上海市方达律师事务所 | G19: 20241024 | H19: 20241105深圳嘉道功程股权投资基金 | I19: 20241105，6亿股，1.15元
A20: 600165 | B20: 宁夏中科生物 | C20: 石嘴山中院 | D20: 20240423 | E20: 20240601 | F20: 20240608 | G20: 20240614 | H20: 20241228湖南醇投实业发展有限公司 | I20: 产投：1.12元，3.5亿股 财投：1.6，5.2亿股 | L20: 否 | M20: 20250917 | S20: 上涨 | U20: 26
A21: 600811 | B21: 东方集团 | C21: 哈尔滨中院 | D21: 20240626 | E21: 20240808 | F21: 20240809 | G21: 20240723 | H21: 14家 | J21: 被立案调查，可能触发重大违法退市 | Q21: 失败
A22: 603007 | B22: 花王 | C22: 镇江中院 | D22: 20220429 | G22: 20220525 | H22: 20230130金华辰顺浩景企业管理合伙企业 | I22: 20241115 | K22: 1.5 | M22: 20240910 | O22: 20241116 | P22: 20241220 | Q22: 成功 | R22: 3 | S22: 上涨 | T22: 等了太久才批准所以大涨 | U22: 24
A23: 525 | B23: 红太阳 | C23: 南京中院 | D23: 20220920 | E23: 20221207 | F23: 20221208 | G23: 20221215 | H23: 20240222曲靖高新技术产业开发区 | M23: 20240918 | N23: 20240919 | O23: 20241102 | P23: 20241112 | Q23: 成功 | R23: 0 | S23: 上涨 | T23: 为什么后面又大跌呢 | U23: 48 | V23: 是，还有否定内控帽子没摘
A24: 300093 | B24: 金刚光伏 | C24: 酒泉中院 | D24: 20240708 | F24: 20250919 | H24: 欧昊集团，4.96,3亿 | I24: 20250610 | J24: 必须在2025年底之前重整完成，否则就要退市 审计都OK的 | L24: 是 | M24: 20250919 | R24: 10
A25: 300091 | B25: 金通灵 | C25: 南通中院 | D25: 20250331 | F25: 20250419 | G25: 20250407 | H25: 汇通达网络股份有限公司，香港上市 | I25: 20250906 1.3996元，7亿股，10亿元 | J25: 无资金占用，有一个投资者虚假陈述纠纷 | L25: 否 | M25: 20260101
A26: 615 | B26: 奥园美谷 | C26: 襄阳中院 | D26: 20241119 | F26: 20241206 | G26: 20241214 | H26: 20250423九州通 | I26: 20250424 九州通1.62元，4.35亿股，7亿 天津信美1.62元，1.21股，2亿 财投1，2.08元，0.42亿股，0.88亿 财投2，2.08元，0.96亿股，2亿元 财投3，2.08元，0.32亿股，0.67亿元 财投4，2.08元，0.54亿股，1.2亿元 财投5，2.08元，0.6亿股，1.2亿元 财投6，2.08元，0.18亿股，0.37亿元 | J26: 必须在2025年底之前重整完成，否则就要退市 审计都OK的 20250726，跟京汉控股的官司输了，很可能被动形成控股股东担保从而导致资金占用，资金占用不能及时消除会影响重整受理 | K26: 否 | L26: 是 | M26: 20251114 | S26: 下跌
A27: 300159 | B27: 新研股份 | C27: 乌鲁木齐中院 | D27: 20250603 | E27: 北京市金杜律师事务所和新疆巨臣律师事务所 | G27: 20250612 | H27: 20250701新疆商贸物流（集团）有限公司 | I27: 20250827，转赠17.94亿股 产投1.3元，5亿股，6.5亿元 | J27: 必须在2025年底之前重整完成，否则就要退市 审计都OK的 | L27: 是 | M27: 20251114 | S27: 下跌
A28: 793 | B28: 华闻集团 | C28: 海口中院 | D28: 20241022 | E28: 华闻集团清算组担 | F28: 20241101 | G28: 20241226 | H28: 20250506海南联合及海南国资运营 | I28: 20250506，5亿股，1.22元 | J28: 还可以拖到明年
A29: 752 | B29: 西藏发展 | C29: 拉萨中院 | D29: 20230721 | E29: 上海锦天城律师事务所 | F29: 20230801 | G29: 20230909 | H29: 20230927西藏盛邦发展有限公司，这个就是现在大股东啊。公司历史问题太混乱了。 | J29: 20231117被立案调查，已经处罚，存在资金占用 20231219，大股东豁免了1.9亿债务所以净资产转正 20250115，大股东又捐赠了1.8亿。到目前，还有原大股东资金占用问题未解决。 | L29: 否 | M29: 20260427
A30: 300147 | B30: 香雪制药 | C30: 广州中院 | D30: 20250206 | E30: 京市金杜(广州)律师事务所 | F30: 20250416 | G30: 20260422 | J30: 无保留意见 | L30: 否
A31: 2620 | B31: 瑞和股份 | C31: 深圳中院 | D31: 20250218 | E31: 佛山市贝思特会计师事务所有限公司 | F31: 20250726 | H31: 深圳市槟城电子股份有限公司，半导体元器件 | I31: 20260515 转赠5.6亿股 产投，2.4亿股，3.9元，9亿 财投，2.3亿股，3.9元 债权人，0.8亿股 | J31: 可能要放到明年去了，因为目前还没有戴星，明年肯定戴星了
A32: 300198 | B32: 纳川股份 | C32: 泉州中院 | D32: 20250318 | E32: 纳川管材科技股份有限公司清算组 | F32: 20250325 | I32: 1.25元，2.7亿元，还有另外两个一致行动人2.2亿元
A33: 851 | B33: 高鸿网络 | C33: 贵阳中院 | D33: 20240712 | F33: 20240824 | G33: 20240820 | J33: 20240730被立案调查 20250808触及重大违法退市 | Q33: 失败
A34: 972 | B34: 中基健康 | C34: 六师中院 | D34: 20250730 | F34: 20250730 | G34: 20250805 | H34: 20250912 | I34: 20250912，8.5亿股，1.81元，新业集团5亿配2.7亿股。财投2.52元，2.85亿股，剩下的债转股 | J34: 重整前本来要发行股份购买新业集团下的新疆新业能源化工有限责任公司的，后来终止了，因这个是借壳上市，估计太难了，放弃了。化工2024收入25亿，净利润5亿。目前先重整保壳，然后再择机注入资产
A35: 300472 | B35: 新元科技 | C35: 抚州中院 | D35: 20250630 | E35: 上海市锦天城律师事务所 | F35: 20250704 | G35: 20250728 | J35: 必须重整成功，否则退市
A36: 691 | B36: 亚太实业 | C36: 兰州中院 | D36: 20250712 | E36: 清算组 | F36: 20250712 | G36: 20250806 | H36: 20250909北京星箭长空测控技术股份有限公司 | I36: 20250913，4亿，1.6亿股，产投2.4元，财投2.65元 | J36: 原实控人跟现实控人打架，后和解。转让股份，用钱堵嘴。 | L36: 是 | M36: 20251126 | Q36: 成功
A37: 2168 | B37: 惠程信息 | C37: 重庆五中院 | D37: 20250804 | F37: 20250809 | G37: 20250809 | H37: 20250902植恩生物技术股份有限公司，净资产16亿，净利润4000万，收入11亿 | I37: 20250911 转赠3.7亿股 产投2.3亿股，1.735元，4亿元 财投0.57亿股，1.835元，1亿元 | J37: 获债权人豁免1.3亿债务 20250929，确认债权7.6亿
A38: 300256 | B38: 星星科技 | C38: 萍乡中院 | D38: 20210818 | E38: 萍乡市人民政府有关部门人员组成的清算组，上海市锦天城律师事务所 | F38: ,20250826 | G38: 20210910 | H38: 20220712浙江立马科技有限公司 承诺24月内注入部分电动车资产，36月内全部注入 12月内在萍乡建设电动车制造集群，三年内净利润不低于1.2亿 | I38: 转赠13.1亿股 产投6亿股，0.75元，4.5亿元 财投1.5亿股，1.5元，2.25亿元 | J38: 20210821被实施退市风险，因为财务纠正后2020年净资产为负 20211204大股东捐赠资产 20211221大股东豁免债务25亿 20211130重大子公司破产清算减少大量债务 经过上面几个手段，净资产终于转正了 20210929被立案调查 20221118处罚落地，2019和2020严重造假 | K38: 是 | M38: 20220526 | N38: 20220713 | O38: 20220804 | P38: 20220825 | Q38: 成功 | R38: 20 | S38: 横盘 | T38: 该案例只有保壳阶段有利润 | U38: 28
A39: 600654 | B39: 中安科 | C39: 武汉中原 | D39: 20211225 | E39: 公司清算组 | F39: 20220707 | G39: 20250804 | H39: 武汉融晶 | I39: 转赠15.26亿股 产投： | M39: 20221105 | N39: 20221105 | O39: 20221207 | P39: 20221207 | Q39: 成功 | R39: 6 | S39: 上涨
A40: 697 | B40: 炼石航空 | C40: 成都中院 | D40: 20250103 | E40: 北京金杜（成都）律师事务所 | G40: 20250621 | H40: 20250911联合体 | I40: 10转6，转增5.2亿股 产投：5.65元，0.97亿股，5.48亿 产投：6.73元,0,97亿股，6亿 | L40: 否 | M40: 20250923 | N40: 20250923 | R40: 50 | S40: 横盘
...

Sheet Sheet5
A2: 45789.368 | C2: 45761.787 | E2: 45762.292
A3: 45789.422 | C3: 45761.79 | D3: =C3-C2 -> 0.0031712963 | E3: 45762.3 | F3: =E3-E2 -> 0.0077893518 | G3: 45763.408
A4: 45789.437 | C4: 45761.794 | D4: =C4-C3 -> 0.0038541667 | E4: 45762.304 | F4: =E4-E3 -> 0.0038888889 | G4: 45763.408 | H4: =G4-G3 -> 8.101853e-05 | M4: 45765.824
A5: 45789.446 | B5: =A5-A4 -> 0.0095949074 | C5: 45761.799 | D5: =C5-C4 -> 0.0046064815 | E5: 45762.312 | F5: =E5-E4 -> 0.0086689815 | G5: 45763.411 | H5: =G5-G4 -> 0.0025578704 | M5: 45765.852
A6: 45789.455 | B6: =A6-A5 -> 0.0085185185 | C6: 45761.804 | D6: =C6-C5 -> 0.0047800926 | E6: 45762.316 | F6: =E6-E5 -> 0.0036689815 | G6: 45763.414 | H6: =G6-G5 -> 0.0035300926
C7: 45761.807 | D7: =C7-C6 -> 0.0031712963 | E7: 45762.335 | F7: =E7-E6 -> 0.018576389 | G7: 45763.424 | H7: =G7-G6 -> 0.01005787
C8: 45761.811 | D8: =C8-C7 -> 0.004375 | E8: 45762.357 | F8: =E8-E7 -> 0.022291667 | G8: 45763.432 | H8: =G8-G7 -> 0.007662037
C9: 45761.818 | D9: =C9-C8 -> 0.0065046296 | E9: 45762.381 | F9: =E9-E8 -> 0.024467593 | G9: 45763.438 | H9: =G9-G8 -> 0.0057407407
A10: 45803.789 | C10: 45761.826 | D10: =C10-C9 -> 0.008275463 | E10: 45762.451 | F10: =E10-E9 -> 0.069398148 | G10: 45763.444 | H10: =G10-G9 -> 0.0063194444
A11: 45803.795 | C11: 45761.836 | D11: =C11-C10 -> 0.010381944 | E11: 45762.526 | F11: =E11-E10 -> 0.074976852 | G11: 45763.45 | H11: =G11-G10 -> 0.0064814815
C12: 45761.845 | D12: =C12-C11 -> 0.0084490741 | E12: 45762.534 | F12: =E12-E11 -> 0.0082523148 | G12: 45763.586
C13: 45761.857 | D13: =C13-C12 -> 0.011921296 | E13: 45762.538 | F13: =E13-E12 -> 0.0036689815 | G13: 45763.596 | H13: =G13-G12 -> 0.010462963 | J13: 45764.49
C14: 45761.866 | D14: =C14-C13 -> 0.0092361111 | E14: 45762.543 | F14: =E14-E13 -> 0.005787037 | G14: 45763.603 | H14: =G14-G13 -> 0.0064814815 | J14: 45764.499 | K14: =J14-J13 -> 0.0091087963
C15: 45761.873 | D15: =C15-C14 -> 0.007349537 | E15: 45762.548 | F15: =E15-E14 -> 0.0047916667 | G15: 45763.616 | H15: =G15-G14 -> 0.013020833 | J15: 45764.504 | K15: =J15-J14 -> 0.0052893519
C16: 45761.889 | D16: =C16-C15 -> 0.016006944 | E16: 45762.553 | F16: =E16-E15 -> 0.0048726852 | G16: 45763.634 | H16: =G16-G15 -> 0.018148148 | J16: 45764.51 | K16: =J16-J15 -> 0.0055902778
C17: 45761.91 | D17: =C17-C16 -> 0.020601852 | E17: 45762.559 | F17: =E17-E16 -> 0.0059027778 | G17: 45763.64 | H17: =G17-G16 -> 0.0062962963 | J17: 45764.523 | K17: =J17-J16 -> 0.013564815
C18: 45761.93 | D18: =C18-C17 -> 0.019780093 | E18: 45762.567 | F18: =E18-E17 -> 0.0077662037 | G18: 45763.647 | H18: =G18-G17 -> 0.0062384259 | J18: 45764.529 | K18: =J18-J17 -> 0.0052430556
C19: 45761.94 | D19: =C19-C18 -> 0.01025463 | E19: 45762.572 | F19: =E19-E18 -> 0.0053240741 | G19: 45763.663 | H19: =G19-G18 -> 0.016354167 | J19: 45764.536 | K19: =J19-J18 -> 0.0069097222
C20: 45761.98 | D20: =C20-C19 -> 0.039884259 | E20: 45762.585 | F20: =E20-E19 -> 0.013217593 | G20: 45763.67 | H20: =G20-G19 -> 0.0065277778 | J20: 45764.554 | K20: =J20-J19 -> 0.018530093
E21: 45762.599 | F21: =E21-E20 -> 0.013819444 | G21: 45763.678 | H21: =G21-G20 -> 0.0085416667 | J21: 45764.575 | K21: =J21-J20 -> 0.020925926
E22: 45762.607 | F22: =E22-E21 -> 0.0078125 | G22: 45763.691 | H22: =G22-G21 -> 0.01318287 | J22: 45764.583 | K22: =J22-J21 -> 0.0081828704
E23: 45762.613 | F23: =E23-E22 -> 0.0059143519 | G23: 45763.697 | H23: =G23-G22 -> 0.0057986111 | J23: 45764.609 | K23: =J23-J22 -> 0.025821759
E24: 45762.624 | F24: =E24-E23 -> 0.011631944 | G24: 45763.709 | H24: =G24-G23 -> 0.011909722 | J24: 45764.622 | K24: =J24-J23 -> 0.012569444
E25: 45762.642 | F25: =E25-E24 -> 0.017523148 | G25: 45763.715 | H25: =G25-G24 -> 0.0062615741 | J25: 45764.633 | K25: =J25-J24 -> 0.011006944
E26: 45762.649 | F26: =E26-E25 -> 0.0073032407 | G26: 45763.722 | H26: =G26-G25 -> 0.0065046296 | J26: 45764.655 | K26: =J26-J25 -> 0.022523148
E27: 45762.666 | F27: =E27-E26 -> 0.016377315 | G27: 45763.732 | H27: =G27-G26 -> 0.010729167 | J27: 45764.666 | K27: =J27-J26 -> 0.010590278
E28: 45762.69 | F28: =E28-E27 -> 0.024270833 | G28: 45763.74 | H28: =G28-G27 -> 0.0071759259 | J28: 45764.705 | K28: =J28-J27 -> 0.039305556
E29: 45762.698 | F29: =E29-E28 -> 0.0080787037 | G29: 45763.747 | H29: =G29-G28 -> 0.0077314815 | J29: 45764.72 | K29: =J29-J28 -> 0.015439815
E30: 45762.712 | F30: =E30-E29 -> 0.013634259 | G30: 45763.771 | H30: =G30-G29 -> 0.0234375 | J30: 45764.739 | K30: =J30-J29 -> 0.018368056
E31: 45762.732 | F31: =E31-E30 -> 0.020277778 | G31: 45763.774 | H31: =G31-G30 -> 0.0028587963 | J31: 45764.741 | K31: =J31-J30 -> 0.0020601852
E32: 45762.735 | F32: =E32-E31 -> 0.0025810185 | G32: 45763.778 | H32: =G32-G31 -> 0.0046759259 | J32: 45764.743 | K32: =J32-J31 -> 0.0018287037
E33: 45762.751 | F33: =E33-E32 -> 0.016238426 | G33: 45763.819 | J33: 45764.746 | K33: =J33-J32 -> 0.0032291667
E34: 45762.759 | F34: =E34-E33 -> 0.0080208333 | G34: 45763.83 | H34: =G34-G33 -> 0.010856481
E35: 45762.771 | F35: =E35-E34 -> 0.012210648 | G35: 45763.843 | H35: =G35-G34 -> 0.013090278
E36: 45762.822 | G36: 45763.864 | H36: =G36-G35 -> 0.02162037
E37: 45762.839 | F37: =E37-E36 -> 0.017141204 | G37: 45763.879 | H37: =G37-G36 -> 0.015127315
E38: 45762.845 | F38: =E38-E37 -> 0.0066203704 | G38: 45763.894 | H38: =G38-G37 -> 0.01412037
E39: 45762.851 | F39: =E39-E38 -> 0.0056828704 | G39: 45763.915 | H39: =G39-G38 -> 0.020925926
E40: 45762.871 | F40: =E40-E39 -> 0.020509259 | G40: 45763.958 | H40: =G40-G39 -> 0.043483796
E41: 45762.875 | F41: =E41-E40 -> 0.0037152778
...

Sheet 月账单
B1: 1380000 | C1: 金额 | D1: 仓位 | F1: 沪深300 | G1: 月份 | H1: ST组合 | I1: 转债组合 | J1: ST组合折算收益 | K1: 转债组合折算收益 | L1: 打新总收益 | M1: 超市策略总收益 | N1: 当月总计 | O1: ST收益 | P1: 转债收益 | Q1: 打新收益 | R1: 超市策略 | S1: 合计 | T1: 持仓不动收益 | U1: 差额 | V1: 雪大师初资产 | W1: 雪大师末资产 | X1: 雪大师实际 | Y1: 雪大师不动 | Z1: 差额 | AC1: 羊哥初资产 | AD1: 羊哥末资产 | AE1: 羊哥实际 | AF1: 羊哥不动 | AG1: 差额
B2: 柳药转债 | C2: =B1-SUM(C3:C35) -> 57400 | D2: =C2/$B$1 -> 0.041594203 | G2: 2025 | O2: 88219 | P2: 44874 | Q2: =9600+66808 -> 76408 | R2: 15830 | S2: =SUM(O2:R2) -> 225331
B3: 小狮子12支 | C3: 120000 | D3: =C3/$B$1 -> 0.086956522 | F3: 0.032 | G3: 202509 | H3: =22094/300000 -> 0.073646667 | I3: =12386/340000 -> 0.036429412 | J3: =H3/1500000*300000 -> 0.014729333 | K3: =I3/1500000*340000 -> 0.0082573333 | L3: =678/1500000 -> 0.000452 | M3: 0 | N3: =SUM(J3:M3) -> 0.023438667
B4: 转债轮动20支 | C4: 380000 | D4: =C4/$B$1 -> 0.27536232 | F4: 0 | G4: 202510 | H4: 0.0405 | I4: -0.0142 | J4: =H4/1500000*380000 -> 0.01026 | K4: =I4/1500000*380000 -> -0.0035973333 | L4: =10900/1500000 -> 0.0072666667 | M4: =10500/1500000 -> 0.007 | N4: =SUM(J4:M4) -> 0.020929333 | O4: 14552 | P4: -5900 | Q4: 10900 | R4: 10500 | S4: =SUM(O4:R4) -> 30052
B5: 万孚转债 | C5: 30000 | D5: =C5/$B$1 -> 0.02173913 | F5: -0.0246 | G5: 202511 | H5: 0.0353 | I5: 0.0023 | J5: =H5/1500000*1000000 -> 0.023533333 | K5: =I5/1500000*400000 -> 0.00061333333 | L5: 0 | M5: 0.006 | N5: =SUM(J5:M5) -> 0.030146667 | S5: 45000
B6: 恒逸转债 | C6: 42000 | D6: =C6/$B$1 -> 0.030434783 | F6: 0.0228 | G6: 202512 | H6: -0.0592 | I6: 0.0255 | J6: =O6/1500000 -> -0.014250667 | K6: =P6/1500000 -> 0.0021706667 | L6: 0 | M6: =R6/1500000 -> -0.008 | N6: =SUM(J6:M6) -> -0.02008 | O6: -21376 | P6: 3256 | Q6: 0 | R6: =9000-21000 -> -12000 | S6: =SUM(O6:R6) -> -30120
B7: 美锦转债 | C7: 42000 | D7: =C7/$B$1 -> 0.030434783 | F7: =SUM(F8:F19) -> -0.0506 | G7: 2026 | N7: =S7/B1 -> 0.018207246 | O7: =SUM(O8:O18) -> -9582 | P7: =SUM(P8:P18) -> 42098 | Q7: =SUM(Q8:Q18) -> 0 | R7: =SUM(R8:R18) -> -7390 | S7: =SUM(S8:S18) -> 25126 | AB7: 2026
B8: 鲁泰转债 | C8: 115000 | D8: =C8/$B$1 -> 0.083333333 | F8: 0.0165 | G8: 202601 | H8: 0 | I8: 0.0831 | J8: =O8/1500000 -> 0 | K8: =P8/1380000 -> 0.04461087 | L8: 0 | M8: =R8/1380000 -> 0.01679058 | N8: =SUM(J8:M8) -> 0.061401449 | O8: 0 | P8: 61563 | Q8: 0 | R8: 23171 | S8: =SUM(O8:R8) -> 84734 | V8: 3441320 | W8: 3802205 | X8: =W8-V8 -> 360885 | Y8: 322691 | Z8: =X8-Y8 -> 38194 | AB8: 202601 | AG8: =AE8-AF8 -> 0
B9: 中国国航 | C9: 46000 | D9: =C9/$B$1 -> 0.033333333 | F9: 0.0009 | G9: 202602 | H9: 0 | I9: 0.0261 | J9: =O9/1500000 -> 0 | K9: =P9/1380000 -> 0.025655072 | L9: 0 | M9: =R9/1380000 -> 0.024687681 | N9: =SUM(J9:M9) -> 0.050342754 | O9: 0 | P9: 35404 | Q9: 0 | R9: 34069 | S9: =SUM(O9:R9) -> 69473 | V9: 3802205 | W9: 3947873 | X9: =W9-V9 -> 145668 | Y9: 78330 | Z9: =X9-Y9 -> 67338 | AB9: 202602 | AG9: =AE9-AF9 -> 0
B10: 南航转债 | C10: 95000 | D10: =C10/$B$1 -> 0.06884058 | E10: 0 | F10: -0.0553 | G10: 202603 | H10: 0 | I10: -0.0666 | J10: =O10/1500000 -> 0 | K10: =P10/1380000 -> -0.043478261 | L10: 0 | M10: =R10/1380000 -> -0.081561594 | N10: =SUM(J10:M10) -> -0.12503986 | O10: 0 | P10: -60000 | Q10: 0 | R10: =-172555-P10 -> -112555 | S10: =SUM(O10:R10) -> -172555 | V10: 3947873 | W10: 3647202 | X10: =W10-V10 -> -300671 | Y10: -354205 | Z10: =X10-Y10 -> 53534 | AB10: 202603 | AE10: -978328 | AF10: -1037315 | AG10: =AE10-AF10 -> 58987
B11: 太阳纸业 | C11: 90000 | D11: =C11/$B$1 -> 0.065217391 | F11: 0.0803 | G11: 202604 | H11: 0 | I11: 0.0023 | J11: =O11/1500000 -> 0 | K11: =P11/1380000 -> 0.0016666667 | L11: 0 | M11: =R11/1380000 -> 0.034782609 | N11: =SUM(J11:M11) -> 0.036449275 | O11: 0 | P11: 2300 | Q11: 0 | R11: 48000 | S11: =SUM(O11:R11) -> 50300 | V11: 3647202 | W11: 3833830 | X11: =W11-V11 -> 186628 | Y11: 216658 | Z11: =X11-Y11 -> -30030 | AB11: 202604 | AE11: 453961 | AF11: 333429 | AG11: =AE11-AF11 -> 120532
B12: 中国海油 | C12: 95000 | D12: =C12/$B$1 -> 0.06884058 | F12: 0.0176 | G12: 202605 | H12: -0.0539 | I12: -0.0334 | J12: =O12/1380000 -> -0.0078586957 | K12: =P12/1380000 -> -0.0093471014 | L12: 0 | M12: =R12/1380000 -> -0.048264493 | N12: =SUM(J12:M12) -> -0.06547029 | O12: -10845 | P12: -12899 | Q12: 0 | R12: -66605 | S12: =SUM(O12:R12) -> -90349 | T12: -82072 | U12: =S12-T12 -> -8277 | V12: =W11 -> 3833830 | W12: 3575152 | X12: =W12-V12 -> -258678 | Y12: =-301136+12852 -> -288284 | Z12: =X12-Y12 -> 29606 | AB12: 202605 | AE12: -1372639 | AF12: -1041718 | AG12: =AE12-AF12 -> -330921
B13: 金煤科技 | C13: 26000 | D13: =C13/$B$1 -> 0.01884058 | F13: 0.0178 | G13: 202606 | H13: -0.1357 | I13: 0.0472 | J13: =O13/1300000 -> -0.028886923 | K13: =P13/1300000 -> 0.0039369231 | L13: 0 | M13: =R13/1300000 -> -0.079981538 | N13: =SUM(J13:M13) -> -0.10493154 | O13: -37553 | P13: 5118 | Q13: 0 | R13: -103976 | S13: =SUM(O13:R13) -> -136411 | T13: -103425 | U13: =S13-T13 -> -32986 | V13: =W12 -> 3575152 | W13: 3315677 | X13: =W13-V13 -> -259475 | Y13: -253164 | Z13: =X13-Y13 -> -6311 | AB13: 202606 | AE13: -1599658 | AF13: -1369778 | AG13: =AE13-AF13 -> -229880
B14: 恒逸石化 | C14: 23000 | D14: =C14/$B$1 -> 0.016666667 | E14: 0 | F14: -0.0786 | G14: 202607 | H14: 0 | I14: 0.1833 | J14: =O14/1130000 -> 0 | K14: =P14/1130000 -> 0.0074469027 | L14: 0 | M14: =R14/1130000 -> 0.058959292 | N14: =SUM(J14:M14) -> 0.066406195 | O14: 0 | P14: 8415 | Q14: 0 | R14: 66624 | S14: =SUM(O14:R14) -> 75039 | T14: 50109 | U14: =S14-T14 -> 24930 | V14: =W13 -> 3315677 | W14: 3444591 | X14: =W14-V14 -> 128914 | Y14: =119044+10000 -> 129044 | Z14: =X14-Y14 -> -130 | AB14: 202607 | AE14: 901848 | AF14: =797126+120000 -> 917126 | AG14: =AE14-AF14 -> -15278
B15: 宏达股份 | C15: 0 | D15: =C15/$B$1 -> 0 | F15: 0.008 | G15: 202608 | H15: 0.1543 | I15: 0.0097 | J15: =O15/1280000 -> 0.030920313 | K15: =P15/1280000 -> 0.002090625 | L15: =Q15/1180000 -> 0 | M15: =R15/1180000 -> 0.072173729 | N15: =SUM(J15:M15) -> 0.10518467 | O15: 39578 | P15: 2676 | Q15: 0 | R15: 85165 | S15: =SUM(O15:R15) -> 127419 | T15: 121910 | U15: =S15-T15 -> 5509 | V15: =W14 -> 3444591 | W15: 3689149 | X15: =W15-V15 -> 244558 | Y15: 235691 | Z15: =X15-Y15 -> 8867 | AB15: 202608 | AE15: 1202381 | AF15: 1047511 | AG15: =AE15-AF15 -> 154870
